Workbook

Sheet IPC
A1: ENVIRONMENT | B1: NITROGEN | C1: PARTENAIRE | D1: E_N | E1: TMIN_F | F1: TMAX_F | G1: TMN_F | H1: FR_F | I1: HT_F | J1: LT_F | K1: LGDD_F | L1: WD_F | M1: WS_F | N1: WSC_MAX | O1: WSC_100_F | P1: WSC_mm_F | Q1: SSR_F | R1: LSR_F | S1: TMIN_CW | T1: TMAX_CW | U1: TMN_CW | V1: FR_CW | W1: HT_CW | X1: LT_CW | Y1: LGDD_CW | Z1: WD_CW | AA1: WS_CW | AB1: WSC_100_CW | AC1: WSC_mm_CW | AD1: SSR_CW | AE1: LSR_CW | AF1: VERN | AG1: TMIN_B | AH1: TMAX_B | AI1: TMN_B | AJ1: FR_B | AK1: HT_B | AL1: LT_B | AM1: LGDD_B | AN1: WD_B | AO1: WS_B | AP1: WSC_100_B | AQ1: WSC_mm_B | AR1: SSR_B | AS1: LSR_B | AT1: TMIN_FLO | AU1: TMAX_FLO | AV1: TMN_FLO | AW1: FR_FLO | AX1: HT_FLO | AY1: LT_FLO | AZ1: LGDD_FLO | BA1: WD_FLO | BB1: WS_FLO | BC1: WSC_100_FLO | BD1: WSC_mm_FLO | BE1: SSR_FLO | BF1: LSR_FLO | BG1: QPT | BH1: TMIN_P300 | BI1: TMAX_P300 | BJ1: TMN_P300 | BK1: FR_P300 | BL1: HT_P300 | BM1: LT_P300 | BN1: WD_P300 | BO1: WS_P300 | BP1: WSC_100_P300 | BQ1: WSC_mm_P300 | BR1: SSR_P300 | BS1: LSR_P300 | BT1: TMN_P600 | BU1: TMAX_P600 | BV1: TMN_P600 | BW1: FR_P600 | BX1: HT_P600 | BY1: LT_P600 | BZ1: WD_P600 | CA1: WS_P600 | CB1: WSC_100_P600 | CC1: WSC_mm_P600 | CD1: SSR_P600 | CE1: LSR_P600 | CF1: TMIN_P1000 | CG1: TMAX_P1000 | CH1: TMN_P100 | CI1: FR_P1000 | CJ1: HT_P1000 | CK1: LT_P1000 | CL1: WD_P1000 | CM1: WS_P1000 | CN1: WSC_100_P1000 | CO1: WSC_mm_P1000 | CP1: SSR_P1000 | CQ1: LSR_P1000 | CR1: AN | CS1: MSA | CT1: NNI | CU1: N | CV1: WSC_I_mm | CW1: WSC_I_100 | CX1: DBI | CY1: DAI | CZ1: RO | DA1: RF
A2: MD11 | B2: N1 | C2: Innolea | D2: =CONCATENATE(A2,"_",B2) -> MD11_N1 | E2: 0 | F2: 28.3 | G2: 13.7 | H2: 0 | I2: 9 | J2: 8 | K2: 1052.2 | L2: 4 | M2: 28 | N2: 122.1 | O2: 34.9 | P2: 42.66 | Q2: 72079.8 | R2: 35 | S2: -5.5 | T2: 19.3 | U2: 4.2 | V2: 18 | W2: 0 | X2: 16 | Y2: 183.7 | Z2: 0 | AA2: 0 | AB2: 80.5 | AC2: 98.32 | AD2: 18424.7 | AE2: 43 | AF2: 15 | AG2: -4.6 | AH2: 16.6 | AI2: 7.2 | AJ2: 13 | AK2: 0 | AL2: 28 | AM2: 531.1 | AN2: 0 | AO2: 0 | AP2: 75.6 | AQ2: 92.36 | AR2: 56159.3 | AS2: 47 | AT2: 3.5 | AU2: 28.1 | AV2: 13.3 | AW2: 0 | AX2: 4 | AY2: 3 | AZ2: 278.3 | BA2: 0 | BB2: 4 | BC2: 40.4 | BD2: 49.29 | BE2: 33462.1 | BF2: 4 | BG2: 1.2 | BH2: 4.3 | BI2: 23 | BJ2: 14.9 | BK2: 0 | BL2: 0 | BM2: 2 | BN2: 12 | BO2: 9 | BP2: 2.3 | BQ2: 2.78 | BR2: 39855.2 | BS2: 3 | BT2: 10 | BU2: 27.9 | BV2: 18 | BW2: 0 | BX2: 4 | BY2: 0 | BZ2: 13 | CA2: 4 | CB2: 0.8 | CC2: 0.96 | CD2: 34533.7 | CE2: 1 | CF2: 11.1 | CG2: 30.8 | CH2: 18.5 | CI2: 0 | CJ2: 9 | CK2: 0 | CL2: 12 | CM2: 10 | CN2: 7.3 | CO2: 8.86 | CP2: 41129.3 | CQ2: 1 | CR2: 284.96 | CS2: 7.12 | CT2: 0.76 | CU2: 30 | CV2: 75.8 | CW2: 62.080262 | CX2: 6 | CY2: 4 | CZ2: 0 | DA2: 20.2
A3: MD11 | B3: N2 | C3: Innolea | D3: =CONCATENATE(A3,"_",B3) -> MD11_N2 | E3: 0 | F3: 28.3 | G3: 13.7 | H3: 0 | I3: 9 | J3: 8 | K3: 1052.2 | L3: 4 | M3: 28 | N3: 122.1 | O3: 34.9 | P3: 42.66 | Q3: 72079.8 | R3: 35 | S3: -5.5 | T3: 19.3 | U3: 4.2 | V3: 18 | W3: 0 | X3: 16 | Y3: 183.7 | Z3: 0 | AA3: 0 | AB3: 80.5 | AC3: 98.32 | AD3: 18424.7 | AE3: 43 | AF3: 15 | AG3: -4.6 | AH3: 16.6 | AI3: 7.3 | AJ3: 13 | AK3: 0 | AL3: 28 | AM3: 541.1 | AN3: 0 | AO3: 0 | AP3: 75.4 | AQ3: 92.11 | AR3: 57394.2 | AS3: 47 | AT3: 3.5 | AU3: 28.1 | AV3: 13.5 | AW3: 0 | AX3: 4 | AY3: 3 | AZ3: 283.6 | BA3: 0 | BB3: 5 | BC3: 38.3 | BD3: 46.73 | BE3: 33044.3 | BF3: 5 | BG3: 1.17 | BH3: 4.3 | BI3: 23 | BJ3: 15 | BK3: 0 | BL3: 0 | BM3: 2 | BN3: 13 | BO3: 8 | BP3: 2.3 | BQ3: 2.8 | BR3: 40908 | BS3: 2 | BT3: 10 | BU3: 27.9 | BV3: 18.2 | BW3: 0 | BX3: 5 | BY3: 0 | BZ3: 13 | CA3: 4 | CB3: 0.8 | CC3: 0.97 | CD3: 35326.8 | CE3: 1 | CF3: 11.1 | CG3: 30.8 | CH3: 18.4 | CI3: 0 | CJ3: 8 | CK3: 0 | CL3: 11 | CM3: 11 | CN3: 8.6 | CO3: 10.45 | CP3: 40432.5 | CQ3: 1 | CR3: 482.4 | CS3: 8.48 | CT3: 1.07 | CU3: 120 | CV3: 80.39 | CW3: 65.839476 | CX3: 4.3 | CY3: 3.7 | CZ3: 0 | DA3: 21.2
A4: LR11 | B4: N1 | C4: INRAE | D4: =CONCATENATE(A4,"_",B4) -> LR11_N1 | E4: -1.2 | F4: 26.9 | G4: 11.6 | H4: 2 | I4: 1 | J4: 15 | K4: 814.3 | L4: 6 | M4: 25 | N4: 197.4 | O4: 33.2 | P4: 65.5 | Q4: 52400.6 | R4: 51 | S4: -5.9 | T4: 12.8 | U4: 2.8 | V4: 21 | W4: 0 | X4: 24 | Y4: 150.1 | Z4: 0 | AA4: 0 | AB4: 84.1 | AC4: 165.93 | AD4: 15716.8 | AE4: 49 | AF4: 45 | AG4: -4 | AH4: 19.4 | AI4: 7.4 | AJ4: 14 | AK4: 0 | AL4: 23 | AM4: 545.9 | AN4: 0 | AO4: 0 | AP4: 95.6 | AQ4: 188.64 | AR4: 46967 | AS4: 57 | AT4: 2.4 | AU4: 24.8 | AV4: 12.1 | AW4: 0 | AX4: 0 | AY4: 2 | AZ4: 254.8 | BA4: 0 | BB4: 0 | BC4: 74.2 | BD4: 146.5 | BE4: 26752.8 | BF4: 8 | BG4: 1.05 | BH4: 3.8 | BI4: 25.2 | BJ4: 14.8 | BK4: 0 | BL4: 1 | BM4: 1 | BN4: 0 | BO4: 6 | BP4: 41.4 | BQ4: 81.73 | BR4: 36541.6 | BS4: 2 | BT4: 6.7 | BU4: 24.2 | BV4: 14.4 | BW4: 0 | BX4: 0 | BY4: 0 | BZ4: 2 | CA4: 19 | CB4: 14.8 | CC4: 29.15 | CD4: 38540.8 | CE4: 1 | CF4: 5.4 | CG4: 27.8 | CH4: 15.4 | CI4: 0 | CJ4: 2 | CK4: 0 | CL4: 6 | CM4: 21 | CN4: 5.5 | CO4: 10.81 | CP4: 41586.1 | CQ4: 8 | CR4: 242.79 | CS4: 4.26 | CT4: 0.84 | CU4: 40 | CV4: 176.79 | CW4: 89.559271 | CX4: 9 | CY4: 7 | CZ4: 0 | DA4: 6.9
A5: LR11 | B5: N2 | C5: INRAE | D5: =CONCATENATE(A5,"_",B5) -> LR11_N2 | E5: -1.2 | F5: 26.9 | G5: 11.6 | H5: 2 | I5: 1 | J5: 15 | K5: 814.3 | L5: 6 | M5: 25 | N5: 197.4 | O5: 33.2 | P5: 65.5 | Q5: 52400.6 | R5: 51 | S5: -5.9 | T5: 12.8 | U5: 2.8 | V5: 21 | W5: 0 | X5: 24 | Y5: 150.1 | Z5: 0 | AA5: 0 | AB5: 84.1 | AC5: 165.93 | AD5: 15716.8 | AE5: 49 | AF5: 45 | AG5: -4 | AH5: 19.4 | AI5: 7.4 | AJ5: 14 | AK5: 0 | AL5: 23 | AM5: 545.9 | AN5: 0 | AO5: 0 | AP5: 95.6 | AQ5: 188.64 | AR5: 46967 | AS5: 57 | AT5: 2.4 | AU5: 24.8 | AV5: 12.1 | AW5: 0 | AX5: 0 | AY5: 2 | AZ5: 254.8 | BA5: 0 | BB5: 0 | BC5: 74.2 | BD5: 146.5 | BE5: 26752.8 | BF5: 8 | BG5: 1.05 | BH5: 3.8 | BI5: 25.2 | BJ5: 14.8 | BK5: 0 | BL5: 1 | BM5: 1 | BN5: 0 | BO5: 6 | BP5: 41.4 | BQ5: 81.73 | BR5: 36541.6 | BS5: 2 | BT5: 6.7 | BU5: 24.2 | BV5: 14.4 | BW5: 0 | BX5: 0 | BY5: 0 | BZ5: 2 | CA5: 19 | CB5: 14.8 | CC5: 29.15 | CD5: 38540.8 | CE5: 1 | CF5: 5.4 | CG5: 27.8 | CH5: 15.4 | CI5: 0 | CJ5: 2 | CK5: 0 | CL5: 6 | CM5: 21 | CN5: 5.5 | CO5: 10.81 | CP5: 41586.1 | CQ5: 8 | CR5: 246.47 | CS5: 4 | CT5: 0.94 | CU5: 130 | CV5: 181.15 | CW5: 91.767984 | CX5: 7.5 | CY5: 4.8 | CZ5: 0 | DA5: 9.8
A6: LR12 | B6: N1 | C6: INRAE | D6: =CONCATENATE(A6,"_",B6) -> LR12_N1 | E6: -0.1 | F6: 29.1 | G6: 11.5 | H6: 1 | I6: 7 | J6: 23 | K6: 1398 | L6: 0 | M6: 89 | N6: 197.4 | O6: 27.7 | P6: 54.76 | Q6: 61960.9 | R6: 102 | S6: -7.9 | T6: 14 | U6: 3.5 | V6: 24 | W6: 0 | X6: 6 | Y6: 157.4 | Z6: 0 | AA6: 0 | AB6: 72 | AC6: 142.08 | AD6: 21928.2 | AE6: 31 | AF6: 8 | AG6: -0.1 | AH6: 21.8 | AI6: 8.6 | AJ6: 1 | AK6: 0 | AL6: 15 | AM6: 258.2 | AN6: 0 | AO6: 0 | AP6: 67.4 | AQ6: 133.02 | AR6: 24313.4 | AS6: 18 | AT6: 1 | AU6: 22.8 | AV6: 10.1 | AW6: 0 | AX6: 0 | AY6: 12 | AZ6: 211.5 | BA6: 0 | BB6: 0 | BC6: 48.9 | BD6: 96.59 | BE6: 34162.2 | BF6: 3 | BG6: 1.62 | BH6: 1.9 | BI6: 23.6 | BJ6: 10.6 | BK6: 0 | BL6: 0 | BM6: 6 | BN6: 0 | BO6: 0 | BP6: 76.3 | BQ6: 150.54 | BR6: 31075.7 | BS6: 14 | BT6: 5.3 | BU6: 29.7 | BV6: 14.9 | BW6: 0 | BX6: 2 | BY6: 0 | BZ6: 0 | CA6: 0 | CB6: 78.3 | CC6: 154.51 | CD6: 44077.1 | CE6: 3 | CF6: 9.4 | CG6: 28.2 | CH6: 15.9 | CI6: 0 | CJ6: 2 | CK6: 0 | CL6: 0 | CM6: 0 | CN6: 78.6 | CO6: 155.11 | CP6: 37246.3 | CQ6: 9 | CR6: 287.08 | CS6: 5.22 | CT6: 0.86 | CU6: 0 | CV6: 0 | CW6: 0 | CX6: 0 | CY6: 0 | CZ6: 0 | DA6: 0
A7: LR12 | B7: N2 | C7: INRAE | D7: =CONCATENATE(A7,"_",B7) -> LR12_N2 | E7: -0.1 | F7: 29.1 | G7: 11.5 | H7: 1 | I7: 7 | J7: 23 | K7: 1398 | L7: 0 | M7: 89 | N7: 197.4 | O7: 27.7 | P7: 54.76 | Q7: 61960.9 | R7: 102 | S7: -7.9 | T7: 14 | U7: 3.5 | V7: 24 | W7: 0 | X7: 6 | Y7: 157.4 | Z7: 0 | AA7: 0 | AB7: 72 | AC7: 142.08 | AD7: 21928.2 | AE7: 31 | AF7: 8 | AG7: -0.1 | AH7: 21.8 | AI7: 8.7 | AJ7: 1 | AK7: 0 | AL7: 15 | AM7: 271.2 | AN7: 0 | AO7: 0 | AP7: 67.3 | AQ7: 132.84 | AR7: 26142.5 | AS7: 18 | AT7: 1 | AU7: 22.8 | AV7: 9.8 | AW7: 0 | AX7: 0 | AY7: 12 | AZ7: 206.1 | BA7: 0 | BB7: 0 | BC7: 48.4 | BD7: 95.54 | BE7: 32794.6 | BF7: 4 | BG7: 1.59 | BH7: 1.9 | BI7: 23.6 | BJ7: 10.7 | BK7: 0 | BL7: 0 | BM7: 6 | BN7: 0 | BO7: 0 | BP7: 77.2 | BQ7: 152.37 | BR7: 30614.2 | BS7: 13 | BT7: 5.3 | BU7: 29.7 | BV7: 14.9 | BW7: 0 | BX7: 2 | BY7: 0 | BZ7: 0 | CA7: 0 | CB7: 78.3 | CC7: 154.61 | CD7: 44077.1 | CE7: 3 | CF7: 9.4 | CG7: 28.2 | CH7: 15.9 | CI7: 0 | CJ7: 2 | CK7: 0 | CL7: 0 | CM7: 0 | CN7: 78.6 | CO7: 155.21 | CP7: 37246.3 | CQ7: 9 | CR7: 428.72 | CS7: 5.73 | CT7: 1.13 | CU7: 80 | CV7: 138.62 | CW7: 70.222898 | CX7: 4.5 | CY7: 4.5 | CZ7: 0 | DA7: 10.9
A8: LR13 | B8: N1 | C8: INRAE | D8: =CONCATENATE(A8,"_",B8) -> LR13_N1 | E8: -3.7 | F8: 28.4 | G8: 10.2 | H8: 6 | I8: 3 | J8: 27 | K8: 1324.4 | L8: 5 | M8: 26 | N8: 197.4 | O8: 70 | P8: 138.27 | Q8: 68962.1 | R8: 111 | S8: -3.3 | T8: 13.5 | U8: 4.4 | V8: 11 | W8: 0 | X8: 32 | Y8: 221.4 | Z8: 0 | AA8: 0 | AB8: 98.3 | AC8: 194.02 | AD8: 22690.6 | AE8: 46 | AF8: 18 | AG8: -2.5 | AH8: 16.3 | AI8: 6.5 | AJ8: 5 | AK8: 0 | AL8: 11 | AM8: 170 | AN8: 0 | AO8: 0 | AP8: 97.6 | AQ8: 192.58 | AR8: 18665.1 | AS8: 19 | AT8: -1.2 | AU8: 22.8 | AV8: 8.2 | AW8: 3 | AX8: 0 | AY8: 8 | AZ8: 172.3 | BA8: 0 | BB8: 0 | BC8: 95.2 | BD8: 187.94 | BE8: 25184.3 | BF8: 8 | BG8: 1.46 | BH8: 0.4 | BI8: 23.6 | BJ8: 11.1 | BK8: 0 | BL8: 0 | BM8: 6 | BN8: 0 | BO8: 0 | BP8: 72.6 | BQ8: 143.32 | BR8: 41572.2 | BS8: 8 | BT8: 4.4 | BU8: 27.8 | BV8: 13.1 | BW8: 0 | BX8: 2 | BY8: 1 | BZ8: 0 | CA8: 0 | CB8: 66.6 | CC8: 131.5 | CD8: 36257.5 | CE8: 5 | CF8: 7.9 | CG8: 24.9 | CH8: 16 | CI8: 0 | CJ8: 0 | CK8: 0 | CL8: 0 | CM8: 0 | CN8: 65.2 | CO8: 128.65 | CP8: 31916.8 | CQ8: 9 | CR8: 257.54 | CS8: 5.65 | CT8: 0.79 | CU8: 0 | CV8: 0 | CW8: 0 | CX8: 0 | CY8: 0 | CZ8: 0 | DA8: 0
A9: LR13 | B9: N2 | C9: INRAE | D9: =CONCATENATE(A9,"_",B9) -> LR13_N2 | E9: -3.7 | F9: 28.4 | G9: 10.2 | H9: 6 | I9: 3 | J9: 27 | K9: 1324.4 | L9: 5 | M9: 26 | N9: 197.4 | O9: 70 | P9: 138.27 | Q9: 68962.1 | R9: 111 | S9: -3.3 | T9: 13.5 | U9: 4.4 | V9: 11 | W9: 0 | X9: 32 | Y9: 221.4 | Z9: 0 | AA9: 0 | AB9: 98.3 | AC9: 194.02 | AD9: 22690.6 | AE9: 46 | AF9: 18 | AG9: -2.5 | AH9: 16.3 | AI9: 6.4 | AJ9: 5 | AK9: 0 | AL9: 12 | AM9: 172.8 | AN9: 0 | AO9: 0 | AP9: 97.5 | AQ9: 192.53 | AR9: 19378 | AS9: 20 | AT9: -1.2 | AU9: 22.8 | AV9: 8.4 | AW9: 3 | AX9: 0 | AY9: 8 | AZ9: 177.1 | BA9: 0 | BB9: 0 | BC9: 94.8 | BD9: 187.11 | BE9: 26874.2 | BF9: 7 | BG9: 1.52 | BH9: 0.4 | BI9: 23.6 | BJ9: 11.2 | BK9: 0 | BL9: 0 | BM9: 5 | BN9: 0 | BO9: 0 | BP9: 72.1 | BQ9: 142.23 | BR9: 39169.4 | BS9: 8 | BT9: 4.4 | BU9: 27.8 | BV9: 13.1 | BW9: 0 | BX9: 2 | BY9: 1 | BZ9: 0 | CA9: 0 | CB9: 66.6 | CC9: 131.5 | CD9: 36257.5 | CE9: 5 | CF9: 7.9 | CG9: 24.9 | CH9: 16 | CI9: 0 | CJ9: 0 | CK9: 0 | CL9: 0 | CM9: 0 | CN9: 65.2 | CO9: 128.65 | CP9: 31916.8 | CQ9: 9 | CR9: 389.02 | CS9: 5.59 | CT9: 1.04 | CU9: 80 | CV9: 185.3 | CW9: 93.870314 | CX9: 4.5 | CY9: 6 | CZ9: 0 | DA9: 13.7
A10: DIJ13 | B10: N1 | C10: Terres Inovia | D10: =CONCATENATE(A10,"_",B10) -> DIJ13_N1 | E10: -6.5 | F10: 25.1 | G10: 8.5 | H10: 12 | I10: 1 | J10: 39 | K10: 1003.2 | L10: 6 | M10: 7 | N10: 122.1 | O10: 84.8 | P10: 103.5 | Q10: 53852.6 | R10: 97 | S10: -6.2 | T10: 15.2 | U10: 1.3 | V10: 34 | W10: 0 | X10: 22 | Y10: 114.1 | Z10: 0 | AA10: 0 | AB10: 97.6 | AC10: 119.16 | AD10: 24071.9 | AE10: 55 | AF10: 31 | AG10: -6.3 | AH10: 24.2 | AI10: 7.6 | AJ10: 6 | AK10: 0 | AL10: 22 | AM10: 363.5 | AN10: 0 | AO10: 0 | AP10: 90.7 | AQ10: 110.8 | AR10: 47545.6 | AS10: 22 | AT10: 4.4 | AU10: 23.6 | AV10: 12.3 | AW10: 0 | AX10: 0 | AY10: 3 | AZ10: 258.9 | BA10: 0 | BB10: 0 | BC10: 92.6 | BD10: 113.08 | BE10: 24685.5 | BF10: 8 | BG10: 0.95 | BH10: 3.7 | BI10: 25.5 | BJ10: 12.2 | BK10: 0 | BL10: 2 | BM10: 2 | BN10: 0 | BO10: 0 | BP10: 94.2 | BQ10: 114.97 | BR10: 37728.5 | BS10: 9 | BT10: 10.3 | BU10: 31.8 | BV10: 18.2 | BW10: 0 | BX10: 5 | BY10: 0 | BZ10: 0 | CA10: 0 | CB10: 77.9 | CC10: 95.12 | CD10: 31646.4 | CE10: 1 | CF10: 9.5 | CG10: 29.2 | CH10: 19.7 | CI10: 0 | CJ10: 11 | CK10: 0 | CL10: 0 | CM10: 0 | CN10: 81.5 | CO10: 99.49 | CP10: 49686.3 | CQ10: 2 | CR10: 973.54 | CS10: 3.04 | CT10: 0.95 | CU10: 120 | CV10: 117.75 | CW10: 96.437346 | CX10: 2 | CY10: 5.7 | CZ10: 1.2 | DA10: 14.6
A11: DIJ13 | B11: N2 | C11: Terres Inovia | D11: =CONCATENATE(A11,"_",B11) -> DIJ13_N2 | E11: -6.5 | F11: 25.1 | G11: 8.5 | H11: 12 | I11: 1 | J11: 39 | K11: 1003.2 | L11: 6 | M11: 7 | N11: 122.1 | O11: 84.8 | P11: 103.5 | Q11: 53852.6 | R11: 97 | S11: -6.2 | T11: 15.2 | U11: 1.3 | V11: 34 | W11: 0 | X11: 22 | Y11: 114.1 | Z11: 0 | AA11: 0 | AB11: 97.6 | AC11: 119.16 | AD11: 24071.9 | AE11: 55 | AF11: 31 | AG11: -6.3 | AH11: 24.2 | AI11: 7.6 | AJ11: 6 | AK11: 0 | AL11: 23 | AM11: 374.8 | AN11: 0 | AO11: 0 | AP11: 90.5 | AQ11: 110.49 | AR11: 48855.8 | AS11: 22 | AT11: 4.7 | AU11: 23.6 | AV11: 12.5 | AW11: 0 | AX11: 0 | AY11: 2 | AZ11: 261.9 | BA11: 0 | BB11: 0 | BC11: 93.2 | BD11: 113.74 | BE11: 24888.4 | BF11: 8 | BG11: 0.95 | BH11: 3.7 | BI11: 25.5 | BJ11: 12.1 | BK11: 0 | BL11: 2 | BM11: 2 | BN11: 0 | BO11: 0 | BP11: 94.4 | BQ11: 115.24 | BR11: 36215.4 | BS11: 9 | BT11: 10.3 | BU11: 31.8 | BV11: 18.2 | BW11: 0 | BX11: 5 | BY11: 0 | BZ11: 0 | CA11: 0 | CB11: 77.9 | CC11: 95.12 | CD11: 31646.4 | CE11: 1 | CF11: 9.5 | CG11: 29.2 | CH11: 19.7 | CI11: 0 | CJ11: 11 | CK11: 0 | CL11: 0 | CM11: 0 | CN11: 81.5 | CO11: 99.49 | CP11: 49686.3 | CQ11: 2 | CR11: 926.57 | CS11: 2.62 | CT11: 1.01 | CU11: 180 | CV11: 114.76 | CW11: 93.988534 | CX11: 2.6 | CY11: 6.2 | CZ11: 0.8 | DA11: 9.9
A12: CH14 | B12: N1 | C12: Euralis | D12: =CONCATENATE(A12,"_",B12) -> CH14_N1 | E12: -0.2 | F12: 31.3 | G12: 14 | H12: 1 | I12: 5 | J12: 5 | K12: 1039.4 | L12: 3 | M12: 28 | N12: 122.1 | O12: 52.3 | P12: 63.9 | Q12: 59193.6 | R12: 48 | S12: -3.5 | T12: 13.2 | U12: 4.5 | V12: 14 | W12: 0 | X12: 28 | Y12: 216.5 | Z12: 0 | AA12: 0 | AB12: 96.8 | AC12: 118.17 | AD12: 19324.8 | AE12: 48 | AF12: 38 | AG12: -1.6 | AH12: 18.8 | AI12: 6.9 | AJ12: 5 | AK12: 0 | AL12: 43 | AM12: 512.9 | AN12: 0 | AO12: 0 | AP12: 96.8 | AQ12: 118.21 | AR12: 49161.8 | AS12: 55 | AT12: -1.1 | AU12: 23.3 | AV12: 10.1 | AW12: 2 | AX12: 0 | AY12: 8 | AZ12: 212.7 | BA12: 0 | BB12: 0 | BC12: 63.6 | BD12: 77.66 | BE12: 25029.9 | BF12: 4 | BG12: 1.18 | BH12: 1.8 | BI12: 20.4 | BJ12: 10.8 | BK12: 0 | BL12: 0 | BM12: 8 | BN12: 0 | BO12: 14 | BP12: 31.6 | BQ12: 38.63 | BR12: 43264.3 | BS12: 5 | BT12: 6.3 | BU12: 24.3 | BV12: 13.2 | BW12: 0 | BX12: 0 | BY12: 0 | BZ12: 0 | CA12: 23 | CB12: 25.1 | CC12: 30.68 | CD12: 39323.4 | CE12: 3 | CF12: 7.9 | CG12: 28.7 | CH12: 18 | CI12: 0 | CJ12: 7 | CK12: 0 | CL12: 6 | CM12: 17 | CN12: 11.5 | CO12: 14.06 | CP12: 49636.8 | CQ12: 0 | CR12: 311.87 | CS12: 4.86 | CT12: 0.99 | CU12: 40 | CV12: 88.22 | CW12: 72.252252 | CX12: 10 | CY12: 4 | CZ12: 0 | DA12: 14.3
A13: CH14 | B13: N2 | C13: Euralis | D13: =CONCATENATE(A13,"_",B13) -> CH14_N2 | E13: -0.2 | F13: 31.3 | G13: 14 | H13: 1 | I13: 5 | J13: 5 | K13: 1039.4 | L13: 3 | M13: 28 | N13: 122.1 | O13: 52.3 | P13: 63.9 | Q13: 59193.6 | R13: 48 | S13: -3.5 | T13: 13.2 | U13: 4.5 | V13: 14 | W13: 0 | X13: 28 | Y13: 216.5 | Z13: 0 | AA13: 0 | AB13: 96.8 | AC13: 118.17 | AD13: 19324.8 | AE13: 48 | AF13: 38 | AG13: -1.6 | AH13: 18.8 | AI13: 6.9 | AJ13: 5 | AK13: 0 | AL13: 44 | AM13: 521 | AN13: 0 | AO13: 0 | AP13: 96.5 | AQ13: 117.8 | AR13: 50433.5 | AS13: 55 | AT13: -1.1 | AU13: 23.3 | AV13: 10.2 | AW13: 2 | AX13: 0 | AY13: 7 | AZ13: 214.8 | BA13: 0 | BB13: 0 | BC13: 62.6 | BD13: 76.47 | BE13: 25583.8 | BF13: 4 | BG13: 1.19 | BH13: 1.8 | BI13: 20.4 | BJ13: 11 | BK13: 0 | BL13: 0 | BM13: 8 | BN13: 0 | BO13: 15 | BP13: 31.1 | BQ13: 37.95 | BR13: 42101.6 | BS13: 6 | BT13: 6.3 | BU13: 24.3 | BV13: 13.2 | BW13: 0 | BX13: 0 | BY13: 0 | BZ13: 0 | CA13: 23 | CB13: 24.4 | CC13: 29.81 | CD13: 41027.9 | CE13: 2 | CF13: 7.9 | CG13: 28.7 | CH13: 18.2 | CI13: 0 | CJ13: 7 | CK13: 0 | CL13: 6 | CM13: 16 | CN13: 10.4 | CO13: 12.7 | CP13: 47269.4 | CQ13: 0 | CR13: 446.5 | CS13: 7.69 | CT13: 1.56 | CU13: 140 | CV13: 104.7 | CW13: 85.749386 | CX13: 5 | CY13: 3 | CZ13: 2 | DA13: 20.6
A14: SEL14 | B14: N1 | C14: MAS seeds | D14: =CONCATENATE(A14,"_",B14) -> SEL14_N1 | E14: 0.4 | F14: 30.7 | G14: 13.5 | H14: 0 | I14: 3 | J14: 7 | K14: 986 | L14: 6 | M14: 18 | N14: 138.9 | O14: 57 | P14: 79.13 | Q14: 45613.9 | R14: 58 | S14: -4 | T14: 11.4 | U14: 4 | V14: 13 | W14: 0 | X14: 22 | Y14: 150.6 | Z14: 0 | AA14: 0 | AB14: 96.3 | AC14: 133.79 | AD14: 13136.5 | AE14: 37 | AF14: 20 | AG14: -1.5 | AH14: 19.4 | AI14: 7.2 | AJ14: 4 | AK14: 0 | AL14: 57 | AM14: 668.4 | AN14: 0 | AO14: 0 | AP14: 95.6 | AQ14: 132.79 | AR14: 55591.5 | AS14: 71 | AT14: 1.9 | AU14: 12.5 | AV14: 11.2 | AW14: 0 | AX14: 0 | AY14: 8 | AZ14: 236 | BA14: 0 | BB14: 0 | BC14: 59.6 | BD14: 82.82 | BE14: 28503.8 | BF14: 3 | BG14: 1.21 | BH14: 3.5 | BI14: 20.4 | BJ14: 11.8 | BK14: 0 | BL14: 0 | BM14: 5 | BN14: 0 | BO14: 6 | BP14: 47.3 | BQ14: 65.65 | BR14: 31889.2 | BS14: 9 | BT14: 5.1 | BU14: 23.3 | BV14: 13.5 | BW14: 0 | BX14: 0 | BY14: 0 | BZ14: 0 | CA14: 0 | CB14: 51.4 | CC14: 71.4 | CD14: 39087.5 | CE14: 1 | CF14: 9.3 | CG14: 27.9 | CH14: 18.4 | CI14: 0 | CJ14: 4 | CK14: 0 | CL14: 0 | CM14: 1 | CN14: 47.9 | CO14: 66.59 | CP14: 44548.1 | CQ14: 2 | CR14: NA | CS14: NA | CT14: NA | CU14: 80 | CV14: 124.6 | CW14: 89.704824 | CX14: 4 | CY14: 4.3 | CZ14: 1.9 | DA14: 15.5
A15: SEL14 | B15: N2 | C15: MAS seeds | D15: =CONCATENATE(A15,"_",B15) -> SEL14_N2 | E15: 0.4 | F15: 30.7 | G15: 13.5 | H15: 0 | I15: 3 | J15: 7 | K15: 986 | L15: 6 | M15: 18 | N15: 138.9 | O15: 57 | P15: 79.13 | Q15: 45613.9 | R15: 58 | S15: -4 | T15: 11.4 | U15: 4 | V15: 13 | W15: 0 | X15: 22 | Y15: 150.6 | Z15: 0 | AA15: 0 | AB15: 96.3 | AC15: 133.79 | AD15: 13136.5 | AE15: 37 | AF15: 20 | AG15: -1.5 | AH15: 19.4 | AI15: 7.3 | AJ15: 4 | AK15: 0 | AL15: 61 | AM15: 714 | AN15: 0 | AO15: 0 | AP15: 94.3 | AQ15: 131.03 | AR15: 61951.4 | AS15: 71 | AT15: 1.9 | AU15: 12.5 | AV15: 11.6 | AW15: 0 | AX15: 0 | AY15: 8 | AZ15: 243.6 | BA15: 0 | BB15: 3 | BC15: 51.2 | BD15: 71.06 | BE15: 31409.5 | BF15: 3 | BG15: 1.29 | BH15: 4.4 | BI15: 20.4 | BJ15: 11.9 | BK15: 0 | BL15: 0 | BM15: 1 | BN15: 0 | BO15: 3 | BP15: 51.1 | BQ15: 70.96 | BR15: 33207.7 | BS15: 9 | BT15: 8 | BU15: 26.7 | BV15: 14.4 | BW15: 0 | BX15: 1 | BY15: 0 | BZ15: 0 | CA15: 0 | CB15: 50 | CC15: 69.44 | CD15: 34796.6 | CE15: 2 | CF15: 11.9 | CG15: 27.9 | CH15: 18.6 | CI15: 0 | CJ15: 4 | CK15: 0 | CL15: 0 | CM15: 4 | CN15: 43.7 | CO15: 60.76 | CP15: 42975.8 | CQ15: 2 | CR15: NA | CS15: NA | CT15: NA | CU15: 160 | CV15: 120.44 | CW15: 86.709863 | CX15: 4 | CY15: 5.2 | CZ15: 1.3 | DA15: 9.9
A16: PRE14 | B16: N1 | C16: RAGT | D16: =CONCATENATE(A16,"_",B16) -> PRE14_N1 | E16: 0.5 | F16: 31.2 | G16: 12.3 | H16: 0 | I16: 1 | J16: 10 | K16: 934.4 | L16: 1 | M16: 20 | N16: 153.6 | O16: 62.5 | P16: 96.07 | Q16: 49166.8 | R16: 56 | S16: -2.5 | T16: 9.9 | U16: 4.9 | V16: 6 | W16: 0 | X16: 15 | Y16: 122.5 | Z16: 0 | AA16: 0 | AB16: 95.7 | AC16: 147 | AD16: 7216.5 | AE16: 25 | AF16: 12 | AG16: -1.7 | AH16: 20.5 | AI16: 7.1 | AJ16: 3 | AK16: 0 | AL16: 55 | AM16: 764.3 | AN16: 0 | AO16: 0 | AP16: 95.1 | AQ16: 146.06 | AR16: 59012.4 | AS16: 83 | AT16: 3.6 | AU16: 21 | AV16: 11.7 | AW16: 0 | AX16: 0 | AY16: 4 | AZ16: 246.3 | BA16: 0 | BB16: 0 | BC16: 54.5 | BD16: 83.72 | BE16: 28763.3 | BF16: 5 | BG16: 1.17 | BH16: 5.7 | BI16: 19.2 | BJ16: 12.3 | BK16: 0 | BL16: 0 | BM16: 0 | BN16: 0 | BO16: 5 | BP16: 38.9 | BQ16: 59.82 | BR16: 36014.1 | BS16: 6 | BT16: 8.6 | BU16: 24.6 | BV16: 15.2 | BW16: 0 | BX16: 0 | BY16: 0 | BZ16: 0 | CA16: 17 | CB16: 28.7 | CC16: 44.05 | CD16: 32304.7 | CE16: 3 | CF16: 8.9 | CG16: 26.3 | CH16: 17.6 | CI16: 0 | CJ16: 1 | CK16: 0 | CL16: 0 | CM16: 21 | CN16: 18.1 | CO16: 27.83 | CP16: 43119.8 | CQ16: 4 | CR16: 201.71 | CS16: 3.51 | CT16: 0.69 | CU16: 50 | CV16: 117.22 | CW16: 76.315104 | CX16: 5.4 | CY16: 6.4 | CZ16: 0 | DA16: 13.9
A17: PRE14 | B17: N2 | C17: RAGT | D17: =CONCATENATE(A17,"_",B17) -> PRE14_N2 | E17: 0.5 | F17: 31.2 | G17: 12.3 | H17: 0 | I17: 1 | J17: 10 | K17: 934.4 | L17: 1 | M17: 20 | N17: 153.6 | O17: 62.5 | P17: 96.07 | Q17: 49166.8 | R17: 56 | S17: -2.5 | T17: 9.9 | U17: 4.9 | V17: 6 | W17: 0 | X17: 15 | Y17: 122.5 | Z17: 0 | AA17: 0 | AB17: 95.7 | AC17: 147 | AD17: 7216.5 | AE17: 25 | AF17: 12 | AG17: -1.7 | AH17: 20.5 | AI17: 7.2 | AJ17: 3 | AK17: 0 | AL17: 55 | AM17: 778.9 | AN17: 0 | AO17: 0 | AP17: 94.9 | AQ17: 145.7 | AR17: 60514.1 | AS17: 83 | AT17: 3.6 | AU17: 21 | AV17: 11.7 | AW17: 0 | AX17: 0 | AY17: 4 | AZ17: 245 | BA17: 0 | BB17: 0 | BC17: 53.6 | BD17: 82.27 | BE17: 28736.3 | BF17: 5 | BG17: 1.17 | BH17: 5.7 | BI17: 20.6 | BJ17: 12.4 | BK17: 0 | BL17: 0 | BM17: 0 | BN17: 0 | BO17: 6 | BP17: 38.1 | BQ17: 58.55 | BR17: 37313 | BS17: 6 | BT17: 8.6 | BU17: 26.3 | BV17: 15.3 | BW17: 0 | BX17: 0 | BY17: 0 | BZ17: 0 | CA17: 17 | CB17: 28.6 | CC17: 43.95 | CD17: 32337.8 | CE17: 3 | CF17: 10.6 | CG17: 26.3 | CH17: 17.4 | CI17: 0 | CJ17: 1 | CK17: 0 | CL17: 1 | CM17: 21 | CN17: 16.7 | CO17: 25.71 | CP17: 41373.8 | CQ17: 4 | CR17: 379.69 | CS17: 4.09 | CT17: 1.05 | CU17: 170 | CV17: 108.76 | CW17: 70.807292 | CX17: 4.2 | CY17: 6.7 | CZ17: 0 | DA17: 11
A18: VER14 | B18: N1 | C18: Syngenta | D18: =CONCATENATE(A18,"_",B18) -> VER14_N1 | E18: -0.1 | F18: 30.7 | G18: 12.4 | H18: 1 | I18: 2 | J18: 7 | K18: 906.7 | L18: 2 | M18: 34 | N18: 189.6 | O18: 42.8 | P18: 81.09 | Q18: 46235.9 | R18: 58 | S18: -2.8 | T18: 9.6 | U18: 4.1 | V18: 7 | W18: 0 | X18: 22 | Y18: 127.8 | Z18: 0 | AA18: 0 | AB18: 88.6 | AC18: 168.04 | AD18: 8803 | AE18: 31 | AF18: 29 | AG18: -1.5 | AH18: 20 | AI18: 6.9 | AJ18: 5 | AK18: 0 | AL18: 65 | AM18: 775.5 | AN18: 0 | AO18: 0 | AP18: 95 | AQ18: 180.05 | AR18: 60647.8 | AS18: 84 | AT18: 3.2 | AU18: 20.6 | AV18: 10.6 | AW18: 0 | AX18: 0 | AY18: 6 | AZ18: 223.1 | BA18: 0 | BB18: 0 | BC18: 65.6 | BD18: 124.42 | BE18: 27230.7 | BF18: 5 | BG18: 1.22 | BH18: 4.3 | BI18: 24.4 | BJ18: 12.2 | BK18: 0 | BL18: 0 | BM18: 1 | BN18: 0 | BO18: 0 | BP18: 62.9 | BQ18: 119.22 | BR18: 37198.9 | BS18: 7 | BT18: 7.4 | BU18: 25.5 | BV18: 15.2 | BW18: 0 | BX18: 2 | BY18: 0 | BZ18: 0 | CA18: 0 | CB18: 69.6 | CC18: 131.88 | CD18: 28883.1 | CE18: 5 | CF18: 8.6 | CG18: 25.9 | CH18: 16.4 | CI18: 0 | CJ18: 1 | CK18: 0 | CL18: 0 | CM18: 0 | CN18: 65.5 | CO18: 124.15 | CP18: 42337.2 | CQ18: 3 | CR18: 205.74 | CS18: 2.85 | CT18: 0.82 | CU18: 30 | CV18: 166.98 | CW18: 88.06962 | CX18: 6 | CY18: 3 | CZ18: 0 | DA18: 8.8
A19: VER14 | B19: N2 | C19: Syngenta | D19: =CONCATENATE(A19,"_",B19) -> VER14_N2 | E19: -0.1 | F19: 30.7 | G19: 12.4 | H19: 1 | I19: 2 | J19: 7 | K19: 906.7 | L19: 2 | M19: 34 | N19: 189.6 | O19: 42.8 | P19: 81.09 | Q19: 46235.9 | R19: 58 | S19: -2.8 | T19: 9.6 | U19: 4.1 | V19: 7 | W19: 0 | X19: 22 | Y19: 127.8 | Z19: 0 | AA19: 0 | AB19: 88.6 | AC19: 168.04 | AD19: 8803 | AE19: 31 | AF19: 29 | AG19: -1.5 | AH19: 20 | AI19: 7 | AJ19: 5 | AK19: 0 | AL19: 65 | AM19: 775.5 | AN19: 0 | AO19: 0 | AP19: 94.8 | AQ19: 179.65 | AR19: 60993.4 | AS19: 85 | AT19: 3.2 | AU19: 20.6 | AV19: 10.4 | AW19: 0 | AX19: 0 | AY19: 6 | AZ19: 218.5 | BA19: 0 | BB19: 0 | BC19: 65 | BD19: 123.25 | BE19: 27449.9 | BF19: 5 | BG19: 1.26 | BH19: 4.3 | BI19: 24.4 | BJ19: 12.4 | BK19: 0 | BL19: 0 | BM19: 1 | BN19: 0 | BO19: 0 | BP19: 63.4 | BQ19: 120.12 | BR19: 38204.6 | BS19: 6 | BT19: 7.4 | BU19: 25.5 | BV19: 15.3 | BW19: 0 | BX19: 2 | BY19: 0 | BZ19: 0 | CA19: 0 | CB19: 69.8 | CC19: 132.37 | CD19: 29336.8 | CE19: 5 | CF19: 8.6 | CG19: 25.9 | CH19: 16.3 | CI19: 0 | CJ19: 1 | CK19: 0 | CL19: 0 | CM19: 0 | CN19: 65 | CO19: 123.17 | CP19: 41022.1 | CQ19: 4 | CR19: 292.41 | CS19: 3.3 | CT19: 1.12 | CU19: 90 | CV19: 175.81 | CW19: 92.726793 | CX19: 3.8 | CY19: 3.9 | CZ19: 1.8 | DA19: 11.8
A20: MD15 | B20: N1 | C20: Innolea | D20: =CONCATENATE(A20,"_",B20) -> MD15_N1 | E20: -0.1 | F20: 29.6 | G20: 15 | H20: 1 | I20: 25 | J20: 15 | K20: 1666.4 | L20: 16 | M20: 65 | N20: 122.1 | O20: 23 | P20: 28.06 | Q20: 102739.1 | R20: 60 | S20: -4.8 | T20: 15.7 | U20: 4.9 | V20: 19 | W20: 0 | X20: 23 | Y20: 265.6 | Z20: 0 | AA20: 0 | AB20: 59.2 | AC20: 72.28 | AD20: 31464.5 | AE20: 47 | AF20: 9 | AG20: 0.4 | AH20: 18.9 | AI20: 9.1 | AJ20: 0 | AK20: 0 | AL20: 16 | AM20: 353.1 | AN20: 0 | AO20: 0 | AP20: 85.8 | AQ20: 104.78 | AR20: 39160.4 | AS20: 14 | AT20: 1 | AU20: 26.4 | AV20: 12.1 | AW20: 0 | AX20: 1 | AY20: 6 | AZ20: 253.8 | BA20: 0 | BB20: 0 | BC20: 66.9 | BD20: 81.63 | BE20: 38112.1 | BF20: 1 | BG20: 1.5 | BH20: 6.6 | BI20: 23.7 | BJ20: 15.7 | BK20: 0 | BL20: 0 | BM20: 0 | BN20: 0 | BO20: 5 | BP20: 36.6 | BQ20: 44.65 | BR20: 27356.8 | BS20: 3 | BT20: 9.9 | BU20: 27.6 | BV20: 16.8 | BW20: 0 | BX20: 4 | BY20: 0 | BZ20: 9 | CA20: 9 | CB20: 8.3 | CC20: 10.12 | CD20: 38146.5 | CE20: 1 | CF20: 11.3 | CG20: 32.8 | CH20: 20.5 | CI20: 0 | CJ20: 10 | CK20: 0 | CL20: 19 | CM20: 1 | CN20: 0.8 | CO20: 0.95 | CP20: 46713.1 | CQ20: 0 | CR20: 142.2 | CS20: 2.14 | CT20: 0.89 | CU20: 52 | CV20: 104.58 | CW20: 85.651106 | CX20: 5 | CY20: 5 | CZ20: 0 | DA20: 11.2
A21: MD15 | B21: N2 | C21: Innolea | D21: =CONCATENATE(A21,"_",B21) -> MD15_N2 | E21: -0.1 | F21: 29.6 | G21: 15 | H21: 1 | I21: 25 | J21: 15 | K21: 1666.4 | L21: 16 | M21: 65 | N21: 122.1 | O21: 23 | P21: 28.06 | Q21: 102739.1 | R21: 60 | S21: -4.8 | T21: 15.7 | U21: 4.9 | V21: 19 | W21: 0 | X21: 23 | Y21: 265.6 | Z21: 0 | AA21: 0 | AB21: 59.2 | AC21: 72.28 | AD21: 31646.5 | AE21: 47 | AF21: 9 | AG21: 0.4 | AH21: 18.9 | AI21: 9 | AJ21: 0 | AK21: 0 | AL21: 17 | AM21: 359.3 | AN21: 0 | AO21: 0 | AP21: 85.8 | AQ21: 104.79 | AR21: 40713.6 | AS21: 14 | AT21: 1 | AU21: 26.4 | AV21: 12.6 | AW21: 0 | AX21: 1 | AY21: 5 | AZ21: 264.7 | BA21: 0 | BB21: 1 | BC21: 64.3 | BD21: 78.5 | BE21: 38607.9 | BF21: 1 | BG21: 1.46 | BH21: 6.6 | BI21: 23.7 | BJ21: 15.7 | BK21: 0 | BL21: 0 | BM21: 0 | BN21: 0 | BO21: 5 | BP21: 36.8 | BQ21: 44.99 | BR21: 26176.1 | BS21: 4 | BT21: 9.9 | BU21: 27.6 | BV21: 16.7 | BW21: 0 | BX21: 4 | BY21: 0 | BZ21: 10 | CA21: 8 | CB21: 6.4 | CC21: 7.8 | CD21: 39497.1 | CE21: 0 | CF21: 12.4 | CG21: 32.8 | CH21: 20.7 | CI21: 0 | CJ21: 10 | CK21: 0 | CL21: 18 | CM21: 2 | CN21: 1.5 | CO21: 1.83 | CP21: 46286.1 | CQ21: 0 | CR21: 223.18 | CS21: 2.65 | CT21: 1.2 | CU21: 122 | CV21: 104.63 | CW21: 85.692056 | CX21: 5 | CY21: 5 | CZ21: 0 | DA21: 11.2
A22: LR15 | B22: N1 | C22: INRAE | D22: =CONCATENATE(A22,"_",B22) -> LR15_N1 | E22: -2.6 | F22: 26.4 | G22: 12.1 | H22: 2 | I22: 4 | J22: 13 | K22: 1329.4 | L22: 2 | M22: 46 | N22: 197.4 | O22: 46 | P22: 90.85 | Q22: 65143.3 | R22: 82 | S22: -4.4 | T22: 14.6 | U22: 4.9 | V22: 21 | W22: 0 | X22: 24 | Y22: 292.8 | Z22: 0 | AA22: 0 | AB22: 99.1 | AC22: 195.58 | AD22: 26499.5 | AE22: 53 | AF22: 17 | AG22: -0.4 | AH22: 15.6 | AI22: 5.4 | AJ22: 1 | AK22: 0 | AL22: 18 | AM22: 308.2 | AN22: 0 | AO22: 0 | AP22: 92.2 | AQ22: 182.01 | AR22: 32406 | AS22: 22 | AT22: 1.9 | AU22: 25 | AV22: 12.8 | AW22: 0 | AX22: 1 | AY22: 6 | AZ22: 268.7 | BA22: 0 | BB22: 0 | BC22: 71 | BD22: 140.11 | BE22: 38573.9 | BF22: 5 | BG22: 1.44 | BH22: 3.3 | BI22: 22.8 | BJ22: 12.9 | BK22: 0 | BL22: 0 | BM22: 2 | BN22: 0 | BO22: 0 | BP22: 64.3 | BQ22: 126.91 | BR22: 31162.9 | BS22: 8 | BT22: 5.7 | BU22: 25.3 | BV22: 14.1 | BW22: 0 | BX22: 1 | BY22: 0 | BZ22: 0 | CA22: 0 | CB22: 50.3 | CC22: 99.24 | CD22: 40993.4 | CE22: 2 | CF22: 9.4 | CG22: 33.9 | CH22: 18.3 | CI22: 0 | CJ22: 7 | CK22: 0 | CL22: 0 | CM22: 3 | CN22: 42 | CO22: 82.88 | CP22: 49259.5 | CQ22: 2 | CR22: 228.28 | CS22: 5.01 | CT22: 0.77 | CU22: 0 | CV22: 0 | CW22: 0 | CX22: 0 | CY22: 0 | CZ22: 0 | DA22: 0
A23: LR15 | B23: N2 | C23: INRAE | D23: =CONCATENATE(A23,"_",B23) -> LR15_N2 | E23: -2.6 | F23: 26.4 | G23: 12.1 | H23: 2 | I23: 4 | J23: 13 | K23: 1329.4 | L23: 2 | M23: 46 | N23: 197.4 | O23: 46 | P23: 90.85 | Q23: 65143.3 | R23: 82 | S23: -4.4 | T23: 14.6 | U23: 4.9 | V23: 21 | W23: 0 | X23: 24 | Y23: 292.8 | Z23: 0 | AA23: 0 | AB23: 99.1 | AC23: 195.58 | AD23: 26499.5 | AE23: 53 | AF23: 17 | AG23: -0.4 | AH23: 15.6 | AI23: 5.4 | AJ23: 1 | AK23: 0 | AL23: 18 | AM23: 308.2 | AN23: 0 | AO23: 0 | AP23: 92.2 | AQ23: 182.01 | AR23: 32406 | AS23: 22 | AT23: 1.9 | AU23: 25 | AV23: 12.8 | AW23: 0 | AX23: 1 | AY23: 6 | AZ23: 268.7 | BA23: 0 | BB23: 0 | BC23: 71 | BD23: 140.11 | BE23: 38573.9 | BF23: 5 | BG23: 1.44 | BH23: 3.3 | BI23: 22.8 | BJ23: 12.9 | BK23: 0 | BL23: 0 | BM23: 2 | BN23: 0 | BO23: 0 | BP23: 64.3 | BQ23: 126.91 | BR23: 31162.9 | BS23: 8 | BT23: 5.7 | BU23: 25.3 | BV23: 14.1 | BW23: 0 | BX23: 1 | BY23: 0 | BZ23: 0 | CA23: 0 | CB23: 50.3 | CC23: 99.24 | CD23: 40993.4 | CE23: 2 | CF23: 9.4 | CG23: 33.9 | CH23: 18.3 | CI23: 0 | CJ23: 7 | CK23: 0 | CL23: 0 | CM23: 3 | CN23: 42 | CO23: 82.88 | CP23: 49259.5 | CQ23: 2 | CR23: 309.83 | CS23: 5.68 | CT23: 0.9 | CU23: 40 | CV23: 193.87 | CW23: 98.211753 | CX23: 1 | CY23: 5 | CZ23: 1 | DA23: 6.9
A24: YEB15 | B24: N1 | C24: Limagrain | D24: =CONCATENATE(A24,"_",B24) -> YEB15_N1 | E24: 3.1 | F24: 26.6 | G24: 13.1 | H24: 0 | I24: 3 | J24: 4 | K24: 1161.7 | L24: 1 | M24: 67 | N24: 197.4 | O24: 23.5 | P24: 46.3 | Q24: 72394.8 | R24: 42 | S24: -5.8 | T24: 16 | U24: 4.3 | V24: 33 | W24: 0 | X24: 49 | Y24: 430.9 | Z24: 0 | AA24: 0 | AB24: 79.9 | AC24: 157.77 | AD24: 40902.6 | AE24: 88 | AF24: 31 | AG24: -1.4 | AH24: 20.7 | AI24: 8.2 | AJ24: 2 | AK24: 0 | AL24: 21 | AM24: 285.4 | AN24: 0 | AO24: 0 | AP24: 88.5 | AQ24: 174.62 | AR24: 41995.9 | AS24: 11 | AT24: 4.5 | AU24: 24.1 | AV24: 12.8 | AW24: 0 | AX24: 0 | AY24: 2 | AZ24: 269.1 | BA24: 0 | BB24: 0 | BC24: 70.1 | BD24: 138.37 | BE24: 34493.9 | BF24: 4 | BG24: 1.28 | BH24: 5.2 | BI24: 25.4 | BJ24: 13.8 | BK24: 0 | BL24: 1 | BM24: 0 | BN24: 0 | BO24: 0 | BP24: 62.1 | BQ24: 122.61 | BR24: 44451.6 | BS24: 0 | BT24: 9.9 | BU24: 32.5 | BV24: 17.1 | BW24: 0 | BX24: 4 | BY24: 0 | BZ24: 0 | CA24: 12 | CB24: 25.5 | CC24: 50.41 | CD24: 40268.7 | CE24: 1 | CF24: 9.1 | CG24: 36.2 | CH24: 20.2 | CI24: 0 | CJ24: 9 | CK24: 0 | CL24: 17 | CM24: 4 | CN24: 0.5 | CO24: 0.96 | CP24: 47902.7 | CQ24: 0 | CR24: 287.29 | CS24: 4.92 | CT24: 0.85 | CU24: 35 | CV24: 178.85 | CW24: 90.602837 | CX24: 4 | CY24: 3 | CZ24: 0 | DA24: 28.2
A25: YEB15 | B25: N2 | C25: Limagrain | D25: =CONCATENATE(A25,"_",B25) -> YEB15_N2 | E25: 3.1 | F25: 26.6 | G25: 13.1 | H25: 0 | I25: 3 | J25: 4 | K25: 1161.7 | L25: 1 | M25: 67 | N25: 197.4 | O25: 23.5 | P25: 46.3 | Q25: 72394.8 | R25: 42 | S25: -5.8 | T25: 16 | U25: 4.3 | V25: 33 | W25: 0 | X25: 49 | Y25: 430.9 | Z25: 0 | AA25: 0 | AB25: 79.9 | AC25: 157.77 | AD25: 40902.6 | AE25: 88 | AF25: 31 | AG25: -1.4 | AH25: 20.7 | AI25: 8.2 | AJ25: 2 | AK25: 0 | AL25: 21 | AM25: 285.4 | AN25: 0 | AO25: 0 | AP25: 88.2 | AQ25: 174.62 | AR25: 41995.9 | AS25: 11 | AT25: 4.5 | AU25: 24.1 | AV25: 12.8 | AW25: 0 | AX25: 0 | AY25: 2 | AZ25: 269.1 | BA25: 0 | BB25: 0 | BC25: 70.1 | BD25: 138.37 | BE25: 34493.9 | BF25: 4 | BG25: 1.28 | BH25: 5.2 | BI25: 25.4 | BJ25: 13.8 | BK25: 0 | BL25: 1 | BM25: 0 | BN25: 0 | BO25: 0 | BP25: 62.1 | BQ25: 122.61 | BR25: 44451.6 | BS25: 0 | BT25: 9.9 | BU25: 32.5 | BV25: 17.1 | BW25: 0 | BX25: 4 | BY25: 0 | BZ25: 0 | CA25: 12 | CB25: 25.5 | CC25: 50.41 | CD25: 40268.7 | CE25: 1 | CF25: 9.1 | CG25: 36.2 | CH25: 20.2 | CI25: 0 | CJ25: 9 | CK25: 0 | CL25: 17 | CM25: 4 | CN25: 0.5 | CO25: 0.96 | CP25: 47902.7 | CQ25: 0 | CR25: 586.57 | CS25: 6.03 | CT25: 1.44 | CU25: 147 | CV25: 179.7 | CW25: 91.033435 | CX25: 4 | CY25: 5.3 | CZ25: 0 | DA25: 17.3
A26: SEL15 | B26: N1 | C26: MAS seeds | D26: =CONCATENATE(A26,"_",B26) -> SEL15_N1 | E26: 0.5 | F26: 26.9 | G26: 13 | H26: 0 | I26: 4 | J26: 6 | K26: 1063.2 | L26: 8 | M26: 21 | N26: 138.9 | O26: 38.1 | P26: 52.98 | Q26: 60224.2 | R26: 57 | S26: -5.6 | T26: 12.9 | U26: 4.4 | V26: 28 | W26: 0 | X26: 46 | Y26: 401.3 | Z26: 0 | AA26: 0 | AB26: 94.8 | AC26: 131.67 | AD26: 27777 | AE26: 89 | AF26: 23 | AG26: -2.2 | AH26: 20.6 | AI26: 7.9 | AJ26: 6 | AK26: 0 | AL26: 21 | AM26: 325.5 | AN26: 0 | AO26: 0 | AP26: 89.8 | AQ26: 127.73 | AR26: 41435.6 | AS26: 21 | AT26: 3 | AU26: 25.5 | AV26: 12.8 | AW26: 0 | AX26: 1 | AY26: 4 | AZ26: 269.4 | BA26: 0 | BB26: 0 | BC26: 58.2 | BD26: 80.81 | BE26: 32782.3 | BF26: 6 | BG26: 1.22 | BH26: 4.4 | BI26: 26.1 | BJ26: 13.7 | BK26: 0 | BL26: 1 | BM26: 1 | BN26: 0 | BO26: 0 | BP26: 80.4 | BQ26: 111.66 | BR26: 37046 | BS26: 4 | BT26: 7.1 | BU26: 31.6 | BV26: 17 | BW26: 0 | BX26: 3 | BY26: 0 | BZ26: 0 | CA26: 7 | CB26: 36.3 | CC26: 50.39 | CD26: 33174.4 | CE26: 2 | CF26: 8.9 | CG26: 36 | CH26: 19.9 | CI26: 0 | CJ26: 9 | CK26: 0 | CL26: 8 | CM26: 13 | CN26: 6.6 | CO26: 9.18 | CP26: 43766.7 | CQ26: 1 | CR26: NA | CS26: NA | CT26: NA | CU26: 50 | CV26: 131.95 | CW26: 94.9964 | CX26: 3.1 | CY26: 6.8 | CZ26: 1.3 | DA26: 6.5
A27: SEL15 | B27: N2 | C27: MAS seeds | D27: =CONCATENATE(A27,"_",B27) -> SEL15_N2 | E27: 0.5 | F27: 26.9 | G27: 13 | H27: 0 | I27: 4 | J27: 6 | K27: 1063.2 | L27: 8 | M27: 21 | N27: 138.9 | O27: 38.1 | P27: 52.98 | Q27: 60224.2 | R27: 57 | S27: -5.6 | T27: 12.9 | U27: 4.4 | V27: 28 | W27: 0 | X27: 46 | Y27: 401.3 | Z27: 0 | AA27: 0 | AB27: 94.8 | AC27: 131.67 | AD27: 27777 | AE27: 89 | AF27: 23 | AG27: -2.2 | AH27: 20.6 | AI27: 7.8 | AJ27: 6 | AK27: 0 | AL27: 21 | AM27: 313.1 | AN27: 0 | AO27: 0 | AP27: 90.2 | AQ27: 125.24 | AR27: 39694.8 | AS27: 21 | AT27: 3 | AU27: 25.5 | AV27: 12.79 | AW27: 0 | AX27: 1 | AY27: 4 | AZ27: 268.5 | BA27: 0 | BB27: 0 | BC27: 57.4 | BD27: 79.71 | BE27: 34049 | BF27: 5 | BG27: 1.27 | BH27: 4.4 | BI27: 26.1 | BJ27: 13.6 | BK27: 0 | BL27: 1 | BM27: 1 | BN27: 0 | BO27: 0 | BP27: 81.7 | BQ27: 113.48 | BR27: 35738.4 | BS27: 5 | BT27: 7.1 | BU27: 31.6 | BV27: 16.9 | BW27: 0 | BX27: 3 | BY27: 0 | BZ27: 0 | CA27: 7 | CB27: 37.8 | CC27: 52.54 | CD27: 34956.1 | CE27: 2 | CF27: 8.9 | CG27: 36 | CH27: 19.9 | CI27: 0 | CJ27: 9 | CK27: 0 | CL27: 8 | CM27: 13 | CN27: 7.1 | CO27: 9.91 | CP27: 43766.7 | CQ27: 1 | CR27: NA | CS27: NA | CT27: NA | CU27: 130 | CV27: 135.24 | CW27: 97.365011 | CX27: 4.3 | CY27: 4.4 | CZ27: 3.6 | DA27: 14.1
A28: PRE15 | B28: N1 | C28: RAGT | D28: =CONCATENATE(A28,"_",B28) -> PRE15_N1 | E28: 4.4 | F28: 26.3 | G28: 12.8 | H28: 0 | I28: 2 | J28: 4 | K28: 1035.4 | L28: 0 | M28: 27 | N28: 153.6 | O28: 46.2 | P28: 70.96 | Q28: 50931.1 | R28: 61 | S28: -3.5 | T28: 13.6 | U28: 4.4 | V28: 22 | W28: 0 | X28: 61 | Y28: 426.7 | Z28: 0 | AA28: 0 | AB28: 95.2 | AC28: 146.19 | AD28: 31498.1 | AE28: 94 | AF28: 49 | AG28: -1.6 | AH28: 24.2 | AI28: 8 | AJ28: 2 | AK28: 0 | AL28: 22 | AM28: 327.6 | AN28: 0 | AO28: 0 | AP28: 89.8 | AQ28: 137.97 | AR28: 45159.4 | AS28: 15 | AT28: 2.6 | AU28: 22.5 | AV28: 11.6 | AW28: 0 | AX28: 0 | AY28: 5 | AZ28: 243.5 | BA28: 0 | BB28: 0 | BC28: 61.1 | BD28: 93.88 | BE28: 32231 | BF28: 4 | BG28: 1.32 | BH28: 6.3 | BI28: 23.6 | BJ28: 13.3 | BK28: 0 | BL28: 0 | BM28: 0 | BN28: 0 | BO28: 6 | BP28: 41.4 | BQ28: 63.54 | BR28: 36677.9 | BS28: 4 | BT28: 8.6 | BU28: 31.1 | BV28: 16.3 | BW28: 0 | BX28: 3 | BY28: 0 | BZ28: 7 | CA28: 12 | CB28: 9.1 | CC28: 13.93 | CD28: 39258.6 | CE28: 2 | CF28: 9.6 | CG28: 33.6 | CH28: 19.2 | CI28: 0 | CJ28: 7 | CK28: 0 | CL28: 8 | CM28: 13 | CN28: 3.5 | CO28: 5.39 | CP28: 40621.3 | CQ28: 2 | CR28: NA | CS28: 7.75 | CT28: NA | CU28: 75 | CV28: 144.77 | CW28: 94.251302 | CX28: 2 | CY28: 2 | CZ28: 3 | DA28: 34.4
A29: PRE15 | B29: N2 | C29: RAGT | D29: =CONCATENATE(A29,"_",B29) -> PRE15_N2 | E29: 4.4 | F29: 26.3 | G29: 12.8 | H29: 0 | I29: 2 | J29: 4 | K29: 1035.4 | L29: 0 | M29: 27 | N29: 153.6 | O29: 46.2 | P29: 70.96 | Q29: 50931.1 | R29: 61 | S29: -3.5 | T29: 13.6 | U29: 4.4 | V29: 22 | W29: 0 | X29: 61 | Y29: 426.7 | Z29: 0 | AA29: 0 | AB29: 95.2 | AC29: 146.19 | AD29: 31498.1 | AE29: 94 | AF29: 49 | AG29: -1.6 | AH29: 21.7 | AI29: 7.6 | AJ29: 2 | AK29: 0 | AL29: 22 | AM29: 297.5 | AN29: 0 | AO29: 0 | AP29: 90.4 | AQ29: 138.83 | AR29: 41913.4 | AS29: 15 | AT29: 2.6 | AU29: 24.2 | AV29: 11.9 | AW29: 0 | AX29: 0 | AY29: 5 | AZ29: 249.1 | BA29: 0 | BB29: 0 | BC29: 62.5 | BD29: 95.98 | BE29: 32208.3 | BF29: 4 | BG29: 1.29 | BH29: 6.3 | BI29: 23.6 | BJ29: 13.3 | BK29: 0 | BL29: 0 | BM29: 0 | BN29: 0 | BO29: 4 | BP29: 44.7 | BQ29: 68.6 | BR29: 37295.5 | BS29: 3 | BT29: 8.6 | BU29: 31.1 | BV29: 15.8 | BW29: 0 | BX29: 3 | BY29: 0 | BZ29: 6 | CA29: 14 | CB29: 11.2 | CC29: 17.14 | CD29: 40592.6 | CE29: 3 | CF29: 9.6 | CG29: 33.6 | CH29: 19.1 | CI29: 0 | CJ29: 7 | CK29: 0 | CL29: 9 | CM29: 12 | CN29: 3.6 | CO29: 5.51 | CP29: 39704.2 | CQ29: 2 | CR29: NA | CS29: 8.46 | CT29: NA | CU29: 175 | CV29: 124.45 | CW29: 81.022135 | CX29: 3.7 | CY29: 5.4 | CZ29: 1.3 | DA29: 17.5
A30: VER15 | B30: N1 | C30: Syngenta | D30: =CONCATENATE(A30,"_",B30) -> VER15_N1 | E30: 3.4 | F30: 25.7 | G30: 12.5 | H30: 0 | I30: 2 | J30: 4 | K30: 1112.2 | L30: 0 | M30: 36 | N30: 189.6 | O30: 41.5 | P30: 78.77 | Q30: 59277.7 | R30: 64 | S30: -3.8 | T30: 14.5 | U30: 3.9 | V30: 28 | W30: 0 | X30: 57 | Y30: 391.9 | Z30: 0 | AA30: 0 | AB30: 94.5 | AC30: 179.1 | AD30: 32664 | AE30: 95 | AF30: 36 | AG30: -2.5 | AH30: 20.6 | AI30: 7.2 | AJ30: 5 | AK30: 0 | AL30: 18 | AM30: 251.1 | AN30: 0 | AO30: 0 | AP30: 89.9 | AQ30: 170.4 | AR30: 37212.7 | AS30: 14 | AT30: 2.1 | AU30: 24.4 | AV30: 11.2 | AW30: 0 | AX30: 0 | AY30: 5 | AZ30: 235.1 | BA30: 0 | BB30: 0 | BC30: 65.8 | BD30: 127.73 | BE30: 33754.2 | BF30: 5 | BG30: 1.44 | BH30: 5.2 | BI30: 24 | BJ30: 12.6 | BK30: 0 | BL30: 0 | BM30: 0 | BN30: 0 | BO30: 0 | BP30: 57.8 | BQ30: 109.68 | BR30: 38520.3 | BS30: 1 | BT30: 6 | BU30: 31.1 | BV30: 15 | BW30: 0 | BX30: 2 | BY30: 0 | BZ30: 0 | CA30: 3 | CB30: 38.8 | CC30: 73.51 | CD30: 38942.4 | CE30: 1 | CF30: 7.9 | CG30: 33.4 | CH30: 18 | CI30: 0 | CJ30: 7 | CK30: 0 | CL30: 0 | CM30: 23 | CN30: 20.9 | CO30: 39.67 | CP30: 44693.9 | CQ30: 2 | CR30: 75.51 | CS30: 1.19 | CT30: 0.97 | CU30: 50 | CV30: 171.57 | CW30: 90.490506 | CX30: 2 | CY30: 8 | CZ30: 0 | DA30: 0.6
A31: VER15 | B31: N2 | C31: Syngenta | D31: =CONCATENATE(A31,"_",B31) -> VER15_N2 | E31: 3.4 | F31: 25.7 | G31: 12.5 | H31: 0 | I31: 2 | J31: 4 | K31: 1112.2 | L31: 0 | M31: 36 | N31: 189.6 | O31: 41.5 | P31: 78.77 | Q31: 59277.7 | R31: 64 | S31: -3.8 | T31: 14.5 | U31: 3.9 | V31: 28 | W31: 0 | X31: 57 | Y31: 391.9 | Z31: 0 | AA31: 0 | AB31: 94.5 | AC31: 179.1 | AD31: 32664 | AE31: 95 | AF31: 36 | AG31: -2.5 | AH31: 20.6 | AI31: 7.2 | AJ31: 5 | AK31: 0 | AL31: 19 | AM31: 260.7 | AN31: 0 | AO31: 0 | AP31: 89.7 | AQ31: 170 | AR31: 38418.9 | AS31: 14 | AT31: 2.4 | AU31: 24.4 | AV31: 11.4 | AW31: 0 | AX31: 0 | AY31: 4 | AZ31: 239.8 | BA31: 0 | BB31: 0 | BC31: 64.7 | BD31: 122.74 | BE31: 33296.4 | BF31: 6 | BG31: 1.39 | BH31: 5.2 | BI31: 24 | BJ31: 12.6 | BK31: 0 | BL31: 0 | BM31: 0 | BN31: 0 | BO31: 0 | BP31: 57.3 | BQ31: 108.56 | BR31: 39896.8 | BS31: 0 | BT31: 6 | BU31: 31.1 | BV31: 15 | BW31: 0 | BX31: 2 | BY31: 0 | BZ31: 0 | CA31: 5 | CB31: 37.8 | CC31: 71.74 | CD31: 39392.9 | CE31: 1 | CF31: 7.9 | CG31: 33.4 | CH31: 18 | CI31: 0 | CJ31: 7 | CK31: 0 | CL31: 0 | CM31: 23 | CN31: 19.7 | CO31: 37.31 | CP31: 44237.2 | CQ31: 2 | CR31: 175.08 | CS31: 1.91 | CT31: 1.25 | CU31: 130 | CV31: 177.93 | CW31: 93.844937 | CX31: 2.4 | CY31: 5.3 | CZ31: 1.9 | DA31: 11.7
A32: DIJ15 | B32: N1 | C32: Terres Inovia | D32: =CONCATENATE(A32,"_",B32) -> DIJ15_N1 | E32: 0.7 | F32: 25.9 | G32: 12.7 | H32: 0 | I32: 6 | J32: 10 | K32: 1083.1 | L32: 2 | M32: 32 | N32: 122.1 | O32: 55.8 | P32: 68.11 | Q32: 61859.1 | R32: 57 | S32: -6.9 | T32: 13 | U32: 3.3 | V32: 32 | W32: 0 | X32: 49 | Y32: 323.1 | Z32: 0 | AA32: 0 | AB32: 98.8 | AC32: 120.7 | AD32: 31517.5 | AE32: 84 | AF32: 40 | AG32: -2.7 | AH32: 19.4 | AI32: 7.5 | AJ32: 6 | AK32: 0 | AL32: 23 | AM32: 309.1 | AN32: 0 | AO32: 0 | AP32: 84.2 | AQ32: 102.86 | AR32: 46956.4 | AS32: 16 | AT32: 2.8 | AU32: 23.6 | AV32: 13 | AW32: 0 | AX32: 0 | AY32: 1 | AZ32: 273.8 | BA32: 0 | BB32: 1 | BC32: 49.1 | BD32: 59.98 | BE32: 34397.2 | BF32: 5 | BG32: 1.26 | BH32: 5.6 | BI32: 26.9 | BJ32: 14.8 | BK32: 0 | BL32: 3 | BM32: 0 | BN32: 0 | BO32: 1 | BP32: 60.9 | BQ32: 74.34 | BR32: 37483.2 | BS32: 3 | BT32: 5.9 | BU32: 32.5 | BV32: 18.2 | BW32: 0 | BX32: 6 | BY32: 0 | BZ32: 5 | CA32: 12 | CB32: 11 | CC32: 13.48 | CD32: 35285.6 | CE32: 0 | CF32: 9.2 | CG32: 30.3 | CH32: 19.1 | CI32: 0 | CJ32: 9 | CK32: 0 | CL32: 3 | CM32: 18 | CN32: 13.7 | CO32: 16.75 | CP32: 39231.4 | CQ32: 1 | CR32: 300.52 | CS32: 4.2 | CT32: 1.15 | CU32: 60 | CV32: 110.25 | CW32: 90.29484 | CX32: 6 | CY32: 4.5 | CZ32: 3 | DA32: 17.1
A33: DIJ15 | B33: N2 | C33: Terres Inovia | D33: =CONCATENATE(A33,"_",B33) -> DIJ15_N2 | E33: 0.7 | F33: 25.9 | G33: 12.7 | H33: 0 | I33: 6 | J33: 10 | K33: 1083.1 | L33: 2 | M33: 32 | N33: 122.1 | O33: 55.8 | P33: 68.11 | Q33: 61859.1 | R33: 57 | S33: -6.9 | T33: 13 | U33: 3.3 | V33: 32 | W33: 0 | X33: 49 | Y33: 323.1 | Z33: 0 | AA33: 0 | AB33: 98.8 | AC33: 120.7 | AD33: 31517.5 | AE33: 84 | AF33: 40 | AG33: -2.7 | AH33: 19.4 | AI33: 7.5 | AJ33: 6 | AK33: 0 | AL33: 23 | AM33: 309.1 | AN33: 0 | AO33: 0 | AP33: 84.2 | AQ33: 102.86 | AR33: 46956.4 | AS33: 16 | AT33: 2.8 | AU33: 23.6 | AV33: 13 | AW33: 0 | AX33: 0 | AY33: 1 | AZ33: 273.8 | BA33: 0 | BB33: 1 | BC33: 49.1 | BD33: 59.98 | BE33: 34397.2 | BF33: 5 | BG33: 1.26 | BH33: 5.6 | BI33: 26.9 | BJ33: 14.8 | BK33: 0 | BL33: 3 | BM33: 0 | BN33: 0 | BO33: 1 | BP33: 60.9 | BQ33: 74.34 | BR33: 37483.2 | BS33: 3 | BT33: 5.9 | BU33: 32.5 | BV33: 18.2 | BW33: 0 | BX33: 6 | BY33: 0 | BZ33: 5 | CA33: 12 | CB33: 11 | CC33: 13.48 | CD33: 35285.6 | CE33: 0 | CF33: 9.2 | CG33: 30.3 | CH33: 19.1 | CI33: 0 | CJ33: 9 | CK33: 0 | CL33: 3 | CM33: 18 | CN33: 13.7 | CO33: 16.75 | CP33: 39231.4 | CQ33: 1 | CR33: 357.19 | CS33: 4.29 | CT33: 1.3 | CU33: 140 | CV33: 108.73 | CW33: 89.049959 | CX33: 6.3 | CY33: 5 | CZ33: 2.6 | DA33: 15.1
A34: LR16 | B34: N1 | C34: INRAE | D34: =CONCATENATE(A34,"_",B34) -> LR16_N1 | E34: 1.6 | F34: 23.8 | G34: 11.5 | H34: 0 | I34: 0 | J34: 16 | K34: 1449.4 | L34: 0 | M34: 50 | N34: 197.4 | O34: 44.4 | P34: 87.66 | Q34: 69684.8 | R34: 99 | S34: -1.6 | T34: 14.4 | U34: 4.1 | V34: 2 | W34: 0 | X34: 9 | Y34: 49.2 | Z34: 0 | AA34: 0 | AB34: 91 | AC34: 179.69 | AD34: 3707.9 | AE34: 12 | AF34: 9 | AG34: -2.4 | AH34: 14.4 | AI34: 7 | AJ34: 6 | AK34: 0 | AL34: 29 | AM34: 399.7 | AN34: 0 | AO34: 0 | AP34: 98.3 | AQ34: 194.04 | AR34: 34188.8 | AS34: 43 | AT34: 0.2 | AU34: 16.1 | AV34: 8.5 | AW34: 0 | AX34: 0 | AY34: 12 | AZ34: 178.5 | BA34: 0 | BB34: 0 | BC34: 95.7 | BD34: 188.91 | BE34: 19329.1 | BF34: 11 | BG34: 1.08 | BH34: 0 | BI34: 20.9 | BJ34: 10.8 | BK34: 0 | BL34: 0 | BM34: 13 | BN34: 0 | BO34: 0 | BP34: 86.8 | BQ34: 171.32 | BR34: 43065.7 | BS34: 8 | BT34: 4.8 | BU34: 21.7 | BV34: 13.9 | BW34: 0 | BX34: 0 | BY34: 1 | BZ34: 0 | CA34: 0 | CB34: 72.6 | CC34: 143.36 | CD34: 27898.6 | CE34: 8 | CF34: 9.6 | CG34: 25.9 | CH34: 16.4 | CI34: 0 | CJ34: 2 | CK34: 0 | CL34: 0 | CM34: 0 | CN34: 76.1 | CO34: 150.13 | CP34: 26241 | CQ34: 16 | CR34: 392.04 | CS34: 5.79 | CT34: 1.04 | CU34: 0 | CV34: 0 | CW34: 0 | CX34: 0 | CY34: 0 | CZ34: 0 | DA34: 0
A35: LR16 | B35: N2 | C35: INRAE | D35: =CONCATENATE(A35,"_",B35) -> LR16_N2 | E35: 1.6 | F35: 23.8 | G35: 11.5 | H35: 0 | I35: 0 | J35: 16 | K35: 1449.4 | L35: 0 | M35: 50 | N35: 197.4 | O35: 44.4 | P35: 87.66 | Q35: 69684.8 | R35: 99 | S35: -1.6 | T35: 14.4 | U35: 4.1 | V35: 2 | W35: 0 | X35: 9 | Y35: 49.2 | Z35: 0 | AA35: 0 | AB35: 91 | AC35: 179.69 | AD35: 3707.9 | AE35: 12 | AF35: 9 | AG35: -2.4 | AH35: 14.4 | AI35: 7 | AJ35: 6 | AK35: 0 | AL35: 29 | AM35: 399.7 | AN35: 0 | AO35: 0 | AP35: 98.3 | AQ35: 194.04 | AR35: 34188.8 | AS35: 43 | AT35: 0.2 | AU35: 16.1 | AV35: 8.5 | AW35: 0 | AX35: 0 | AY35: 12 | AZ35: 178.5 | BA35: 0 | BB35: 0 | BC35: 95.7 | BD35: 188.91 | BE35: 19329.1 | BF35: 11 | BG35: 1.08 | BH35: 0 | BI35: 20.9 | BJ35: 10.8 | BK35: 0 | BL35: 0 | BM35: 13 | BN35: 0 | BO35: 0 | BP35: 86.8 | BQ35: 171.32 | BR35: 43065.7 | BS35: 8 | BT35: 4.8 | BU35: 21.7 | BV35: 13.9 | BW35: 0 | BX35: 0 | BY35: 1 | BZ35: 0 | CA35: 0 | CB35: 72.6 | CC35: 143.36 | CD35: 27898.6 | CE35: 8 | CF35: 9.6 | CG35: 25.9 | CH35: 16.4 | CI35: 0 | CJ35: 2 | CK35: 0 | CL35: 0 | CM35: 0 | CN35: 76.1 | CO35: 150.13 | CP35: 26241 | CQ35: 16 | CR35: 428.96 | CS35: 5.6 | CT35: 1.02 | CU35: 70 | CV35: 195.19 | CW35: 98.880446 | CX35: 3 | CY35: 0 | CZ35: 6 | DA35: 51
A36: AU117 | B36: N1 | C36: Innolea | D36: =CONCATENATE(A36,"_",B36) -> AU117_N1 | E36: -2 | F36: 26.6 | G36: 12.1 | H36: 2 | I36: 4 | J36: 14 | K36: 1074.6 | L36: 18 | M36: 36 | N36: 155.7 | O36: 21.6 | P36: 33.66 | Q36: 67506.7 | R36: 65 | S36: -4.8 | T36: 13.9 | U36: 4 | V36: 15 | W36: 0 | X36: 17 | Y36: 165.5 | Z36: 0 | AA36: 0 | AB36: 40.4 | AC36: 62.88 | AD36: 18621.6 | AE36: 34 | AF36: 18 | AG36: 0.5 | AH36: 19.3 | AI36: 9.6 | AJ36: 0 | AK36: 0 | AL36: 20 | AM36: 482 | AN36: 0 | AO36: 0 | AP36: 52.5 | AQ36: 81.79 | AR36: 43211.9 | AS36: 32 | AT36: 3.3 | AU36: 21.8 | AV36: 11.3 | AW36: 0 | AX36: 0 | AY36: 6 | AZ36: 237.7 | BA36: 0 | BB36: 0 | BC36: 52.3 | BD36: 81.79 | BE36: 27454.6 | BF36: 6 | BG36: 1.16 | BH36: 1.7 | BI36: 22.9 | BJ36: 12.7 | BK36: 0 | BL36: 0 | BM36: 5 | BN36: 4 | BO36: 17 | BP36: 14.1 | BQ36: 21.88 | BR36: 49070 | BS36: 2 | BT36: 8.2 | BU36: 27.4 | BV36: 15.9 | BW36: 0 | BX36: 3 | BY36: 0 | BZ36: 2 | CA36: 18 | CB36: 6.9 | CC36: 10.76 | CD36: 34767.6 | CE36: 2 | CF36: 12.1 | CG36: 31.7 | CH36: 20 | CI36: 0 | CJ36: 10 | CK36: 0 | CL36: 3 | CM36: 18 | CN36: 12.6 | CO36: 19.54 | CP36: 41883.9 | CQ36: 3 | CR36: 415.72 | CS36: 4.55 | CT36: 1.22 | CU36: 0 | CV36: 0 | CW36: 0 | CX36: 0 | CY36: 0 | CZ36: 0 | DA36: 0
A37: AU117 | B37: N2 | C37: Innolea | D37: =CONCATENATE(A37,"_",B37) -> AU117_N2 | E37: -2 | F37: 26.6 | G37: 12.1 | H37: 2 | I37: 4 | J37: 14 | K37: 1074.6 | L37: 18 | M37: 36 | N37: 155.7 | O37: 21.6 | P37: 33.66 | Q37: 67506.7 | R37: 65 | S37: -4.8 | T37: 13.9 | U37: 4 | V37: 15 | W37: 0 | X37: 17 | Y37: 165.5 | Z37: 0 | AA37: 0 | AB37: 40.4 | AC37: 62.88 | AD37: 18621.6 | AE37: 34 | AF37: 18 | AG37: 0.5 | AH37: 19.3 | AI37: 9.7 | AJ37: 0 | AK37: 0 | AL37: 20 | AM37: 492.4 | AN37: 0 | AO37: 0 | AP37: 52.6 | AQ37: 81.9 | AR37: 43852.7 | AS37: 33 | AT37: 3.3 | AU37: 21.8 | AV37: 11.5 | AW37: 0 | AX37: 0 | AY37: 6 | AZ37: 242.1 | BA37: 0 | BB37: 0 | BC37: 52 | BD37: 80.92 | BE37: 29214.6 | BF37: 5 | BG37: 1.21 | BH37: 1.7 | BI37: 22.9 | BJ37: 12.6 | BK37: 0 | BL37: 0 | BM37: 5 | BN37: 4 | BO37: 18 | BP37: 12.7 | BQ37: 19.74 | BR37: 47717.1 | BS37: 2 | BT37: 8.2 | BU37: 27.4 | BV37: 16 | BW37: 0 | BX37: 3 | BY37: 0 | BZ37: 2 | CA37: 17 | CB37: 6.8 | CC37: 10.53 | CD37: 33719.7 | CE37: 2 | CF37: 12.1 | CG37: 31.7 | CH37: 20 | CI37: 0 | CJ37: 10 | CK37: 0 | CL37: 3 | CM37: 18 | CN37: 12.5 | CO37: 19.4 | CP37: 41883.9 | CQ37: 3 | CR37: 413.77 | CS37: 4.55 | CT37: 1.17 | CU37: 60 | CV37: 85.12 | CW37: 54.669236 | CX37: 4 | CY37: 4 | CZ37: 0 | DA37: 51.1
A38: AU217 | B38: N1 | C38: Innolea | D38: =CONCATENATE(A38,"_",B38) -> AU217_N1 | E38: -2 | F38: 26.6 | G38: 12.1 | H38: 2 | I38: 4 | J38: 14 | K38: 1074.6 | L38: 18 | M38: 36 | N38: 157.8 | O38: 21.4 | P38: 33.8 | Q38: 67506.7 | R38: 65 | S38: -4.8 | T38: 13.9 | U38: 4 | V38: 15 | W38: 0 | X38: 17 | Y38: 165.5 | Z38: 0 | AA38: 0 | AB38: 40 | AC38: 63.14 | AD38: 18621.6 | AE38: 34 | AF38: 18 | AG38: 0.5 | AH38: 19.3 | AI38: 9.6 | AJ38: 0 | AK38: 0 | AL38: 20 | AM38: 469.6 | AN38: 0 | AO38: 0 | AP38: 51.9 | AQ38: 81.91 | AR38: 41320.5 | AS38: 32 | AT38: 3.3 | AU38: 21.8 | AV38: 11.3 | AW38: 0 | AX38: 0 | AY38: 5 | AZ38: 238.1 | BA38: 0 | BB38: 0 | BC38: 52.5 | BD38: 82.78 | BE38: 26903 | BF38: 6 | BG38: 1.13 | BH38: 1.7 | BI38: 22.9 | BJ38: 12.8 | BK38: 0 | BL38: 0 | BM38: 6 | BN38: 4 | BO38: 16 | BP38: 15.6 | BQ38: 24.57 | BR38: 50463.4 | BS38: 2 | BT38: 6.5 | BU38: 27.4 | BV38: 15.5 | BW38: 0 | BX38: 3 | BY38: 0 | BZ38: 2 | CA38: 18 | CB38: 6.7 | CC38: 10.55 | CD38: 33809.9 | CE38: 2 | CF38: 10.5 | CG38: 29.3 | CH38: 19.6 | CI38: 0 | CJ38: 9 | CK38: 0 | CL38: 3 | CM38: 18 | CN38: 12.2 | CO38: 19.32 | CP38: 41399.3 | CQ38: 3 | CR38: 198.42 | CS38: 3.38 | CT38: 0.81 | CU38: 0 | CV38: 0 | CW38: 0 | CX38: 0 | CY38: 0 | CZ38: 0 | DA38: 0
A39: AU217 | B39: N2 | C39: Innolea | D39: =CONCATENATE(A39,"_",B39) -> AU217_N2 | E39: -2 | F39: 26.6 | G39: 12.1 | H39: 2 | I39: 4 | J39: 14 | K39: 1074.6 | L39: 18 | M39: 36 | N39: 157.8 | O39: 21.4 | P39: 33.8 | Q39: 67506.7 | R39: 65 | S39: -4.8 | T39: 13.9 | U39: 4 | V39: 15 | W39: 0 | X39: 17 | Y39: 165.5 | Z39: 0 | AA39: 0 | AB39: 40 | AC39: 63.14 | AD39: 18621.6 | AE39: 34 | AF39: 18 | AG39: 0.5 | AH39: 19.3 | AI39: 9.6 | AJ39: 0 | AK39: 0 | AL39: 20 | AM39: 482 | AN39: 0 | AO39: 0 | AP39: 52 | AQ39: 82.05 | AR39: 43211.9 | AS39: 32 | AT39: 3.3 | AU39: 21.8 | AV39: 11.3 | AW39: 0 | AX39: 0 | AY39: 6 | AZ39: 237.7 | BA39: 0 | BB39: 0 | BC39: 52 | BD39: 82.05 | BE39: 27454.6 | BF39: 6 | BG39: 1.16 | BH39: 1.7 | BI39: 22.9 | BJ39: 12.7 | BK39: 0 | BL39: 0 | BM39: 5 | BN39: 4 | BO39: 17 | BP39: 14 | BQ39: 22.05 | BR39: 49070 | BS39: 2 | BT39: 8.2 | BU39: 27.4 | BV39: 15.9 | BW39: 0 | BX39: 3 | BY39: 0 | BZ39: 2 | CA39: 18 | CB39: 6.8 | CC39: 10.7 | CD39: 33719.7 | CE39: 2 | CF39: 12.1 | CG39: 31.7 | CH39: 20 | CI39: 0 | CJ39: 10 | CK39: 0 | CL39: 3 | CM39: 18 | CN39: 12.2 | CO39: 19.22 | CP39: 41883.9 | CQ39: 3 | CR39: 338.73 | CS39: 3.73 | CT39: 1.24 | CU39: 120 | CV39: 87.2 | CW39: 55.259823 | CX39: 3.5 | CY39: 4.5 | CZ39: 0 | DA39: 33.4
A40: BLO17 | B40: N1 | C40: Euralis | D40: =CONCATENATE(A40,"_",B40) -> BLO17_N1 | E40: -0.2 | F40: 31.1 | G40: 12.3 | H40: 1 | I40: 9 | J40: 20 | K40: 1105.9 | L40: 15 | M40: 69 | N40: 146.7 | O40: 10.4 | P40: 15.25 | Q40: 65384.6 | R40: 59 | S40: -7.8 | T40: 11.7 | U40: 2.1 | V40: 32 | W40: 0 | X40: 23 | Y40: 162.2 | Z40: 0 | AA40: 20 | AB40: 36.5 | AC40: 53.5 | AD40: 25649.9 | AE40: 59 | AF40: 47 | AG40: -4.1 | AH40: 17.7 | AI40: 7.7 | AJ40: 6 | AK40: 0 | AL40: 19 | AM40: 445.7 | AN40: 0 | AO40: 0 | AP40: 59.9 | AQ40: 87.86 | AR40: 31075 | AS40: 49 | AT40: 2.9 | AU40: 23.8 | AV40: 11.6 | AW40: 0 | AX40: 0 | AY40: 7 | AZ40: 243.4 | BA40: 0 | BB40: 0 | BC40: 59.2 | BD40: 86.88 | BE40: 31721.3 | BF40: 5 | BG40: 1.3 | BH40: -0.1 | BI40: 22.9 | BJ40: 10.4 | BK40: 1 | BL40: 0 | BM40: 12 | BN40: 0 | BO40: 26 | BP40: 25.1 | BQ40: 36.87 | BR40: 45891.3 | BS40: 5 | BT40: 7.2 | BU40: 29.3 | BV40: 18.4 | BW40: 0 | BX40: 7 | BY40: 0 | BZ40: 0 | CA40: 11 | CB40: 26.2 | CC40: 38.46 | CD40: 33179 | CE40: 1 | CF40: 8.9 | CG40: 35.1 | CH40: 20.3 | CI40: 0 | CJ40: 11 | CK40: 0 | CL40: 10 | CM40: 10 | CN40: 2.9 | CO40: 4.23 | CP40: 45196.7 | CQ40: 1 | CR40: 322.92 | CS40: 3.56 | CT40: 0.82 | CU40: 0 | CV40: 0 | CW40: 0 | CX40: 0 | CY40: 0 | CZ40: 0 | DA40: 0
...

Sheet IPC 0-10
A1: ENVIRONMENT | B1: NITROGEN | C1: PARTENAIRE | D1: E_N | E1: TMIN_F | F1: TMAX_F | G1: TMN_F | H1: FR_F | I1: HT_F | J1: LT_F | K1: LGDD_F | L1: WD_F | M1: WS_F | N1: WSC_MAX | O1: WSC_100_F | P1: WSC_mm_F | Q1: SSR_F | R1: LSR_F | S1: TMIN_CW | T1: TMAX_CW | U1: TMN_CW | V1: FR_CW | W1: HT_CW | X1: LT_CW | Y1: LGDD_CW | Z1: WD_CW | AA1: WS_CW | AB1: WSC_100_CW | AC1: WSC_mm_CW | AD1: SSR_CW | AE1: LSR_CW | AF1: VERN | AG1: TMIN_B | AH1: TMAX_B | AI1: TMN_B | AJ1: FR_B | AK1: HT_B | AL1: LT_B | AM1: LGDD_B | AN1: WD_B | AO1: WS_B | AP1: WSC_100_B | AQ1: WSC_mm_B | AR1: SSR_B | AS1: LSR_B | AT1: TMIN_FLO | AU1: TMAX_FLO | AV1: TMN_FLO | AW1: FR_FLO | AX1: HT_FLO | AY1: LT_FLO | AZ1: LGDD_FLO | BA1: WD_FLO | BB1: WS_FLO | BC1: WSC_100_FLO | BD1: WSC_mm_FLO | BE1: SSR_FLO | BF1: LSR_FLO | BG1: QPT | BH1: TMIN_P300 | BI1: TMAX_P300 | BJ1: TMN_P300 | BK1: FR_P300 | BL1: HT_P300 | BM1: LT_P300 | BN1: WD_P300 | BO1: WS_P300 | BP1: WSC_100_P300 | BQ1: WSC_mm_P300 | BR1: SSR_P300 | BS1: LSR_P300 | BT1: TMN_P600 | BU1: TMAX_P600 | BV1: TMN_P600 | BW1: FR_P600 | BX1: HT_P600 | BY1: LT_P600 | BZ1: WD_P600 | CA1: WS_P600 | CB1: WSC_100_P600 | CC1: WSC_mm_P600 | CD1: SSR_P600 | CE1: LSR_P600 | CF1: TMIN_P1000 | CG1: TMAX_P1000 | CH1: TMN_P100 | CI1: FR_P1000 | CJ1: HT_P1000 | CK1: LT_P1000 | CL1: WD_P1000 | CM1: WS_P1000 | CN1: WSC_100_P1000 | CO1: WSC_mm_P1000 | CP1: SSR_P1000 | CQ1: LSR_P1000 | CR1: AN | CS1: MSA | CT1: NNI | CU1: N | CV1: WSC_I_mm | CW1: WSC_I_100 | CX1: DBI | CY1: DAI | CZ1: RO | DA1: RF
A2: MD11 | B2: N1 | C2: Innolea | D2: =CONCATENATE(A2,"_",B2) -> MD11_N1 | E2: =(IPC!E2-MIN(IPC!E$2:E$78))/(MAX(IPC!E$2:E$78)-MIN(IPC!E$2:E$78))*10 -> 5.9633028 | F2: =(IPC!F2-MIN(IPC!F$2:F$78))/(MAX(IPC!F$2:F$78)-MIN(IPC!F$2:F$78))*10 -> 5.5555556 | G2: =(IPC!G2-MIN(IPC!G$2:G$78))/(MAX(IPC!G$2:G$78)-MIN(IPC!G$2:G$78))*10 -> 8 | H2: =(IPC!H2-MIN(IPC!H$2:H$78))/(MAX(IPC!H$2:H$78)-MIN(IPC!H$2:H$78))*10 -> 0 | I2: =(IPC!I2-MIN(IPC!I$2:I$78))/(MAX(IPC!I$2:I$78)-MIN(IPC!I$2:I$78))*10 -> 2.0454545 | J2: =(IPC!J2-MIN(IPC!J$2:J$78))/(MAX(IPC!J$2:J$78)-MIN(IPC!J$2:J$78))*10 -> 1.1428571 | K2: =(IPC!K2-MIN(IPC!K$2:K$78))/(MAX(IPC!K$2:K$78)-MIN(IPC!K$2:K$78))*10 -> 3.6862664 | L2: =(IPC!L2-MIN(IPC!L$2:L$78))/(MAX(IPC!L$2:L$78)-MIN(IPC!L$2:L$78))*10 -> 2.2222222 | ... V2: =(IPC!V2-MIN(IPC!V$2:V$78))/(MAX(IPC!V$2:V$78)-MIN(IPC!V$2:V$78))*10 -> 3.6363636 | W2: 0 | X2: =(IPC!X2-MIN(IPC!X$2:X$78))/(MAX(IPC!X$2:X$78)-MIN(IPC!X$2:X$78))*10 -> 1.8181818 | Y2: =(IPC!Y2-MIN(IPC!Y$2:Y$78))/(MAX(IPC!Y$2:Y$78)-MIN(IPC!Y$2:Y$78))*10 -> 2.4884366 | Z2: 0 | AA2: =(IPC!AA2-MIN(IPC!AA$2:AA$78))/(MAX(IPC!AA$2:AA$78)-MIN(IPC!AA$2:AA$78))*10 -> 0 | AB2: =(IPC!AB2-MIN(IPC!AB$2:AB$78))/(MAX(IPC!AB$2:AB$78)-MIN(IPC!AB$2:AB$78))*10 -> 7.449118 | AC2: =(IPC!AC2-MIN(IPC!AC$2:AC$78))/(MAX(IPC!AC$2:AC$78)-MIN(IPC!AC$2:AC$78))*10 -> 3.1092612 | AD2: =(IPC!AD2-MIN(IPC!AD$2:AD$78))/(MAX(IPC!AD$2:AD$78)-MIN(IPC!AD$2:AD$78))*10 -> 3.9566928 | AE2: =(IPC!AE2-MIN(IPC!AE$2:AE$78))/(MAX(IPC!AE$2:AE$78)-MIN(IPC!AE$2:AE$78))*10 -> 3.2631579 | AF2: =(IPC!AF2-MIN(IPC!AF$2:AF$78))/(MAX(IPC!AF$2:AF$78)-MIN(IPC!AF$2:AF$78))*10 -> 1.5555556 | AG2: =(IPC!AG2-MIN(IPC!AG$2:AG$78))/(MAX(IPC!AG$2:AG$78)-MIN(IPC!AG$2:AG$78))*10 -> 2.4637681 | AH2: =(IPC!AH2-MIN(IPC!AH$2:AH$78))/(MAX(IPC!AH$2:AH$78)-MIN(IPC!AH$2:AH$78))*10 -> 2.244898 | ... AJ2: =(IPC!AJ2-MIN(IPC!AJ$2:AJ$78))/(MAX(IPC!AJ$2:AJ$78)-MIN(IPC!AJ$2:AJ$78))*10 -> 9.2857143 | AK2: 0 | AL2: =(IPC!AL2-MIN(IPC!AL$2:AL$78))/(MAX(IPC!AL$2:AL$78)-MIN(IPC!AL$2:AL$78))*10 -> 3.2727273 | AM2: =(IPC!AM2-MIN(IPC!AM$2:AM$78))/(MAX(IPC!AM$2:AM$78)-MIN(IPC!AM$2:AM$78))*10 -> 5.9303662 | AN2: 0 | AO2: 0 | AP2: =(IPC!AP2-MIN(IPC!AP$2:AP$78))/(MAX(IPC!AP$2:AP$78)-MIN(IPC!AP$2:AP$78))*10 -> 5.1417004 | AQ2: =(IPC!AQ2-MIN(IPC!AQ$2:AQ$78))/(MAX(IPC!AQ$2:AQ$78)-MIN(IPC!AQ$2:AQ$78))*10 -> 0.7786372 | AR2: =(IPC!AR2-MIN(IPC!AR$2:AR$78))/(MAX(IPC!AR$2:AR$78)-MIN(IPC!AR$2:AR$78))*10 -> 8.6699412 | AS2: =(IPC!AS2-MIN(IPC!AS$2:AS$78))/(MAX(IPC!AS$2:AS$78)-MIN(IPC!AS$2:AS$78))*10 -> 4.8648649 | AT2: =(IPC!AT2-MIN(IPC!AT$2:AT$78))/(MAX(IPC!AT$2:AT$78)-MIN(IPC!AT$2:AT$78))*10 -> 5.8024691 | AU2: =(IPC!AU2-MIN(IPC!AU$2:AU$78))/(MAX(IPC!AU$2:AU$78)-MIN(IPC!AU$2:AU$78))*10 -> 10 | AV2: =(IPC!AV2-MIN(IPC!AV$2:AV$78))/(MAX(IPC!AV$2:AV$78)-MIN(IPC!AV$2:AV$78))*10 -> 8.0952381 | AW2: =(IPC!AW2-MIN(IPC!AW$2:AW$78))/(MAX(IPC!AW$2:AW$78)-MIN(IPC!AW$2:AW$78))*10 -> 0 | ... AZ2: =(IPC!AZ2-MIN(IPC!AZ$2:AZ$78))/(MAX(IPC!AZ$2:AZ$78)-MIN(IPC!AZ$2:AZ$78))*10 -> 7.9759217 | BA2: 0 | BB2: =(IPC!BB2-MIN(IPC!BB$2:BB$78))/(MAX(IPC!BB$2:BB$78)-MIN(IPC!BB$2:BB$78))*10 -> 5.7142857 | BC2: =(IPC!BC2-MIN(IPC!BC$2:BC$78))/(MAX(IPC!BC$2:BC$78)-MIN(IPC!BC$2:BC$78))*10 -> 0.42881647 | BD2: =(IPC!BD2-MIN(IPC!BD$2:BD$78))/(MAX(IPC!BD$2:BD$78)-MIN(IPC!BD$2:BD$78))*10 -> 0.15993003 | BE2: =(IPC!BE2-MIN(IPC!BE$2:BE$78))/(MAX(IPC!BE$2:BE$78)-MIN(IPC!BE$2:BE$78))*10 -> 7.3308505 | BF2: =(IPC!BF2-MIN(IPC!BF$2:BF$78))/(MAX(IPC!BF$2:BF$78)-MIN(IPC!BF$2:BF$78))*10 -> 3 | BG2: =(IPC!BG2-MIN(IPC!BG$2:BG$78))/(MAX(IPC!BG$2:BG$78)-MIN(IPC!BG$2:BG$78))*10 -> 4 | BH2: =(IPC!BH2-MIN(IPC!BH$2:BH$78))/(MAX(IPC!BH$2:BH$78)-MIN(IPC!BH$2:BH$78))*10 -> 7.012987 | BI2: =(IPC!BI2-MIN(IPC!BI$2:BI$78))/(MAX(IPC!BI$2:BI$78)-MIN(IPC!BI$2:BI$78))*10 -> 4.2696629 | ... BV2: =(IPC!BV2-MIN(IPC!BV$2:BV$78))/(MAX(IPC!BV$2:BV$78)-MIN(IPC!BV$2:BV$78))*10 -> 7.2058824 | BW2: 0 | BX2: =(IPC!BX2-MIN(IPC!BX$2:BX$78))/(MAX(IPC!BX$2:BX$78)-MIN(IPC!BX$2:BX$78))*10 -> 5 | BY2: =(IPC!BY2-MIN(IPC!BY$2:BY$78))/(MAX(IPC!BY$2:BY$78)-MIN(IPC!BY$2:BY$78))*10 -> 0 | BZ2: =(IPC!BZ2-MIN(IPC!BZ$2:BZ$78))/(MAX(IPC!BZ$2:BZ$78)-MIN(IPC!BZ$2:BZ$78))*10 -> 10 | CA2: =(IPC!CA2-MIN(IPC!CA$2:CA$78))/(MAX(IPC!CA$2:CA$78)-MIN(IPC!CA$2:CA$78))*10 -> 1.7391304 | CB2: =(IPC!CB2-MIN(IPC!CB$2:CB$78))/(MAX(IPC!CB$2:CB$78)-MIN(IPC!CB$2:CB$78))*10 -> 0 | CC2: =(IPC!CC2-MIN(IPC!CC$2:CC$78))/(MAX(IPC!CC$2:CC$78)-MIN(IPC!CC$2:CC$78))*10 -> 0 | CD2: =(IPC!CD2-MIN(IPC!CD$2:CD$78))/(MAX(IPC!CD$2:CD$78)-MIN(IPC!CD$2:CD$78))*10 -> 6.0898442 | CE2: =(IPC!CE2-MIN(IPC!CE$2:CE$78))/(MAX(IPC!CE$2:CE$78)-MIN(IPC!CE$2:CE$78))*10 -> 1.25 | ... CH2: =(IPC!CH2-MIN(IPC!CH$2:CH$78))/(MAX(IPC!CH$2:CH$78)-MIN(IPC!CH$2:CH$78))*10 -> 5.1666667 | CI2: 0 | CJ2: =(IPC!CJ2-MIN(IPC!CJ$2:CJ$78))/(MAX(IPC!CJ$2:CJ$78)-MIN(IPC!CJ$2:CJ$78))*10 -> 7.5 | CK2: 0 | CL2: =(IPC!CL2-MIN(IPC!CL$2:CL$78))/(MAX(IPC!CL$2:CL$78)-MIN(IPC!CL$2:CL$78))*10 -> 6.3157895 | CM2: =(IPC!CM2-MIN(IPC!CM$2:CM$78))/(MAX(IPC!CM$2:CM$78)-MIN(IPC!CM$2:CM$78))*10 -> 4.3478261 | CN2: =(IPC!CN2-MIN(IPC!CN$2:CN$78))/(MAX(IPC!CN$2:CN$78)-MIN(IPC!CN$2:CN$78))*10 -> 0.7508161 | CO2: =(IPC!CO2-MIN(IPC!CO$2:CO$78))/(MAX(IPC!CO$2:CO$78)-MIN(IPC!CO$2:CO$78))*10 -> 0.46014836 | CP2: =(IPC!CP2-MIN(IPC!CP$2:CP$78))/(MAX(IPC!CP$2:CP$78)-MIN(IPC!CP$2:CP$78))*10 -> 6.350228 | CQ2: =(IPC!CQ2-MIN(IPC!CQ$2:CQ$78))/(MAX(IPC!CQ$2:CQ$78)-MIN(IPC!CQ$2:CQ$78))*10 -> 0.625 | CR2: =(IPC!CR2-MIN(IPC!CR$2:CR$78))/(MAX(IPC!CR$2:CR$78)-MIN(IPC!CR$2:CR$78))*10 -> 2.3323274 | CS2: =(IPC!CS2-MIN(IPC!CS$2:CS$78))/(MAX(IPC!CS$2:CS$78)-MIN(IPC!CS$2:CS$78))*10 -> 8.1344307 | ... DA2: =(IPC!DA2-MIN(IPC!DA$2:DA$78))/(MAX(IPC!DA$2:DA$78)-MIN(IPC!DA$2:DA$78))*10 -> 3.9530333
